2017-01-03 11:00:39,471 INFO org.apache.hadoop.yarn.server.resourcemanager.ResourceManager: STARTUP_MSG: 
/************************************************************
STARTUP_MSG: Starting ResourceManager
STARTUP_MSG:   host = tfs01/192.168.50.11
STARTUP_MSG:   args = []
STARTUP_MSG:   version = 2.7.3
STARTUP_MSG:   build = https://git-wip-us.apache.org/repos/asf/hadoop.git -r baa91f7c6bc9cb92be5982de4719c1c8af91ccff; compiled by 'root' on 2016-08-18T01:41Z
STARTUP_MSG:   java = 1.8.0_101
************************************************************/
2017-01-03 11:00:39,480 INFO org.apache.hadoop.yarn.server.resourcemanager.ResourceManager: registered UNIX signal handlers for [TERM, HUP, INT]
2017-01-03 11:00:39,761 INFO org.apache.hadoop.conf.Configuration: found resource core-site.xml at file:/usr/local/hadoop/etc/hadoop/core-site.xml
2017-01-03 11:00:39,829 INFO org.apache.hadoop.security.Groups: clearing userToGroupsMap cache
2017-01-03 11:00:39,886 INFO org.apache.hadoop.conf.Configuration: found resource yarn-site.xml at file:/usr/local/hadoop/etc/hadoop/yarn-site.xml
2017-01-03 11:00:40,032 INFO org.apache.hadoop.yarn.event.AsyncDispatcher: Registering class org.apache.hadoop.yarn.server.resourcemanager.RMFatalEventType for class org.apache.hadoop.yarn.server.resourcemanager.ResourceManager$RMFatalEventDispatcher
2017-01-03 11:00:40,217 INFO org.apache.hadoop.yarn.server.resourcemanager.security.NMTokenSecretManagerInRM: NMTokenKeyRollingInterval: 86400000ms and NMTokenKeyActivationDelay: 900000ms
2017-01-03 11:00:40,220 INFO org.apache.hadoop.yarn.server.resourcemanager.security.RMContainerTokenSecretManager: ContainerTokenKeyRollingInterval: 86400000ms and ContainerTokenKeyActivationDelay: 900000ms
2017-01-03 11:00:40,225 INFO org.apache.hadoop.yarn.server.resourcemanager.security.AMRMTokenSecretManager: AMRMTokenKeyRollingInterval: 86400000ms and AMRMTokenKeyActivationDelay: 900000 ms
2017-01-03 11:00:40,256 INFO org.apache.hadoop.yarn.event.AsyncDispatcher: Registering class org.apache.hadoop.yarn.server.resourcemanager.recovery.RMStateStoreEventType for class org.apache.hadoop.yarn.server.resourcemanager.recovery.RMStateStore$ForwardingEventHandler
2017-01-03 11:00:40,257 INFO org.apache.hadoop.yarn.event.AsyncDispatcher: Registering class org.apache.hadoop.yarn.server.resourcemanager.NodesListManagerEventType for class org.apache.hadoop.yarn.server.resourcemanager.NodesListManager
2017-01-03 11:00:40,258 INFO org.apache.hadoop.yarn.server.resourcemanager.ResourceManager: Using Scheduler: org.apache.hadoop.yarn.server.resourcemanager.scheduler.capacity.CapacityScheduler
2017-01-03 11:00:40,273 INFO org.apache.hadoop.yarn.event.AsyncDispatcher: Registering class org.apache.hadoop.yarn.server.resourcemanager.scheduler.event.SchedulerEventType for class org.apache.hadoop.yarn.server.resourcemanager.ResourceManager$SchedulerEventDispatcher
2017-01-03 11:00:40,274 INFO org.apache.hadoop.yarn.event.AsyncDispatcher: Registering class org.apache.hadoop.yarn.server.resourcemanager.rmapp.RMAppEventType for class org.apache.hadoop.yarn.server.resourcemanager.ResourceManager$ApplicationEventDispatcher
2017-01-03 11:00:40,275 INFO org.apache.hadoop.yarn.event.AsyncDispatcher: Registering class org.apache.hadoop.yarn.server.resourcemanager.rmapp.attempt.RMAppAttemptEventType for class org.apache.hadoop.yarn.server.resourcemanager.ResourceManager$ApplicationAttemptEventDispatcher
2017-01-03 11:00:40,276 INFO org.apache.hadoop.yarn.event.AsyncDispatcher: Registering class org.apache.hadoop.yarn.server.resourcemanager.rmnode.RMNodeEventType for class org.apache.hadoop.yarn.server.resourcemanager.ResourceManager$NodeEventDispatcher
2017-01-03 11:00:40,337 INFO org.apache.hadoop.metrics2.impl.MetricsConfig: loaded properties from hadoop-metrics2.properties
2017-01-03 11:00:40,401 INFO org.apache.hadoop.metrics2.impl.MetricsSystemImpl: Scheduled snapshot period at 10 second(s).
2017-01-03 11:00:40,401 INFO org.apache.hadoop.metrics2.impl.MetricsSystemImpl: ResourceManager metrics system started
2017-01-03 11:00:40,415 INFO org.apache.hadoop.yarn.event.AsyncDispatcher: Registering class org.apache.hadoop.yarn.server.resourcemanager.RMAppManagerEventType for class org.apache.hadoop.yarn.server.resourcemanager.RMAppManager
2017-01-03 11:00:40,421 INFO org.apache.hadoop.yarn.event.AsyncDispatcher: Registering class org.apache.hadoop.yarn.server.resourcemanager.amlauncher.AMLauncherEventType for class org.apache.hadoop.yarn.server.resourcemanager.amlauncher.ApplicationMasterLauncher
2017-01-03 11:00:40,423 INFO org.apache.hadoop.yarn.server.resourcemanager.RMNMInfo: Registered RMNMInfo MBean
2017-01-03 11:00:40,424 INFO org.apache.hadoop.yarn.security.YarnAuthorizationProvider: org.apache.hadoop.yarn.security.ConfiguredYarnAuthorizer is instiantiated.
2017-01-03 11:00:40,425 INFO org.apache.hadoop.util.HostsFileReader: Refreshing hosts (include/exclude) list
2017-01-03 11:00:40,426 INFO org.apache.hadoop.conf.Configuration: found resource capacity-scheduler.xml at file:/usr/local/hadoop/etc/hadoop/capacity-scheduler.xml
2017-01-03 11:00:40,468 INFO org.apache.hadoop.yarn.server.resourcemanager.scheduler.capacity.CapacitySchedulerConfiguration: max alloc mb per queue for root is undefined
2017-01-03 11:00:40,468 INFO org.apache.hadoop.yarn.server.resourcemanager.scheduler.capacity.CapacitySchedulerConfiguration: max alloc vcore per queue for root is undefined
2017-01-03 11:00:40,476 INFO org.apache.hadoop.yarn.server.resourcemanager.scheduler.capacity.ParentQueue: root, capacity=1.0, asboluteCapacity=1.0, maxCapacity=1.0, asboluteMaxCapacity=1.0, state=RUNNING, acls=ADMINISTER_QUEUE:*SUBMIT_APP:*, labels=*,
, reservationsContinueLooking=true
2017-01-03 11:00:40,476 INFO org.apache.hadoop.yarn.server.resourcemanager.scheduler.capacity.ParentQueue: Initialized parent-queue root name=root, fullname=root
2017-01-03 11:00:40,484 INFO org.apache.hadoop.yarn.server.resourcemanager.scheduler.capacity.CapacitySchedulerConfiguration: max alloc mb per queue for root.default is undefined
2017-01-03 11:00:40,484 INFO org.apache.hadoop.yarn.server.resourcemanager.scheduler.capacity.CapacitySchedulerConfiguration: max alloc vcore per queue for root.default is undefined
2017-01-03 11:00:40,485 INFO org.apache.hadoop.yarn.server.resourcemanager.scheduler.capacity.LeafQueue: Initializing default
capacity = 1.0 [= (float) configuredCapacity / 100 ]
asboluteCapacity = 1.0 [= parentAbsoluteCapacity * capacity ]
maxCapacity = 1.0 [= configuredMaxCapacity ]
absoluteMaxCapacity = 1.0 [= 1.0 maximumCapacity undefined, (parentAbsoluteMaxCapacity * maximumCapacity) / 100 otherwise ]
userLimit = 100 [= configuredUserLimit ]
userLimitFactor = 1.0 [= configuredUserLimitFactor ]
maxApplications = 10000 [= configuredMaximumSystemApplicationsPerQueue or (int)(configuredMaximumSystemApplications * absoluteCapacity)]
maxApplicationsPerUser = 10000 [= (int)(maxApplications * (userLimit / 100.0f) * userLimitFactor) ]
usedCapacity = 0.0 [= usedResourcesMemory / (clusterResourceMemory * absoluteCapacity)]
absoluteUsedCapacity = 0.0 [= usedResourcesMemory / clusterResourceMemory]
maxAMResourcePerQueuePercent = 0.1 [= configuredMaximumAMResourcePercent ]
minimumAllocationFactor = 0.875 [= (float)(maximumAllocationMemory - minimumAllocationMemory) / maximumAllocationMemory ]
maximumAllocation = <memory:8192, vCores:32> [= configuredMaxAllocation ]
numContainers = 0 [= currentNumContainers ]
state = RUNNING [= configuredState ]
acls = ADMINISTER_QUEUE:*SUBMIT_APP:* [= configuredAcls ]
nodeLocalityDelay = 40
labels=*,
nodeLocalityDelay = 40
reservationsContinueLooking = true
preemptionDisabled = true

2017-01-03 11:00:40,486 INFO org.apache.hadoop.yarn.server.resourcemanager.scheduler.capacity.CapacityScheduler: Initialized queue: default: capacity=1.0, absoluteCapacity=1.0, usedResources=<memory:0, vCores:0>, usedCapacity=0.0, absoluteUsedCapacity=0.0, numApps=0, numContainers=0
2017-01-03 11:00:40,486 INFO org.apache.hadoop.yarn.server.resourcemanager.scheduler.capacity.CapacityScheduler: Initialized queue: root: numChildQueue= 1, capacity=1.0, absoluteCapacity=1.0, usedResources=<memory:0, vCores:0>usedCapacity=0.0, numApps=0, numContainers=0
2017-01-03 11:00:40,487 INFO org.apache.hadoop.yarn.server.resourcemanager.scheduler.capacity.CapacityScheduler: Initialized root queue root: numChildQueue= 1, capacity=1.0, absoluteCapacity=1.0, usedResources=<memory:0, vCores:0>usedCapacity=0.0, numApps=0, numContainers=0
2017-01-03 11:00:40,487 INFO org.apache.hadoop.yarn.server.resourcemanager.scheduler.capacity.CapacityScheduler: Initialized queue mappings, override: false
2017-01-03 11:00:40,487 INFO org.apache.hadoop.yarn.server.resourcemanager.scheduler.capacity.CapacityScheduler: Initialized CapacityScheduler with calculator=class org.apache.hadoop.yarn.util.resource.DefaultResourceCalculator, minimumAllocation=<<memory:1024, vCores:1>>, maximumAllocation=<<memory:8192, vCores:32>>, asynchronousScheduling=false, asyncScheduleInterval=5ms
2017-01-03 11:00:40,497 INFO org.apache.hadoop.yarn.server.resourcemanager.metrics.SystemMetricsPublisher: YARN system metrics publishing service is not enabled
2017-01-03 11:00:40,497 INFO org.apache.hadoop.yarn.server.resourcemanager.ResourceManager: Transitioning to active state
2017-01-03 11:00:40,509 INFO org.apache.hadoop.yarn.server.resourcemanager.recovery.RMStateStore: Updating AMRMToken
2017-01-03 11:00:40,509 INFO org.apache.hadoop.yarn.server.resourcemanager.security.RMContainerTokenSecretManager: Rolling master-key for container-tokens
2017-01-03 11:00:40,510 INFO org.apache.hadoop.yarn.server.resourcemanager.security.NMTokenSecretManagerInRM: Rolling master-key for nm-tokens
2017-01-03 11:00:40,510 INFO org.apache.hadoop.security.token.delegation.AbstractDelegationTokenSecretManager: Updating the current master key for generating delegation tokens
2017-01-03 11:00:40,510 INFO org.apache.hadoop.yarn.server.resourcemanager.security.RMDelegationTokenSecretManager: storing master key with keyID 1
2017-01-03 11:00:40,511 INFO org.apache.hadoop.yarn.server.resourcemanager.recovery.RMStateStore: Storing RMDTMasterKey.
2017-01-03 11:00:40,512 INFO org.apache.hadoop.security.token.delegation.AbstractDelegationTokenSecretManager: Starting expired delegation token remover thread, tokenRemoverScanInterval=60 min(s)
2017-01-03 11:00:40,512 INFO org.apache.hadoop.security.token.delegation.AbstractDelegationTokenSecretManager: Updating the current master key for generating delegation tokens
2017-01-03 11:00:40,512 INFO org.apache.hadoop.yarn.server.resourcemanager.security.RMDelegationTokenSecretManager: storing master key with keyID 2
2017-01-03 11:00:40,512 INFO org.apache.hadoop.yarn.server.resourcemanager.recovery.RMStateStore: Storing RMDTMasterKey.
2017-01-03 11:00:40,514 INFO org.apache.hadoop.yarn.event.AsyncDispatcher: Registering class org.apache.hadoop.yarn.nodelabels.event.NodeLabelsStoreEventType for class org.apache.hadoop.yarn.nodelabels.CommonNodeLabelsManager$ForwardingEventHandler
2017-01-03 11:00:40,553 INFO org.apache.hadoop.ipc.CallQueueManager: Using callQueue class java.util.concurrent.LinkedBlockingQueue
2017-01-03 11:00:40,565 INFO org.apache.hadoop.ipc.Server: Starting Socket Reader #1 for port 8031
2017-01-03 11:00:40,582 INFO org.apache.hadoop.yarn.factories.impl.pb.RpcServerFactoryPBImpl: Adding protocol org.apache.hadoop.yarn.server.api.ResourceTrackerPB to the server
2017-01-03 11:00:40,583 INFO org.apache.hadoop.ipc.Server: IPC Server Responder: starting
2017-01-03 11:00:40,583 INFO org.apache.hadoop.ipc.Server: IPC Server listener on 8031: starting
2017-01-03 11:00:40,598 INFO org.apache.hadoop.ipc.CallQueueManager: Using callQueue class java.util.concurrent.LinkedBlockingQueue
2017-01-03 11:00:40,604 INFO org.apache.hadoop.ipc.Server: Starting Socket Reader #1 for port 8030
2017-01-03 11:00:40,611 INFO org.apache.hadoop.yarn.factories.impl.pb.RpcServerFactoryPBImpl: Adding protocol org.apache.hadoop.yarn.api.ApplicationMasterProtocolPB to the server
2017-01-03 11:00:40,611 INFO org.apache.hadoop.ipc.Server: IPC Server Responder: starting
2017-01-03 11:00:40,612 INFO org.apache.hadoop.ipc.Server: IPC Server listener on 8030: starting
2017-01-03 11:00:40,655 INFO org.apache.hadoop.ipc.CallQueueManager: Using callQueue class java.util.concurrent.LinkedBlockingQueue
2017-01-03 11:00:40,656 INFO org.apache.hadoop.ipc.Server: Starting Socket Reader #1 for port 8032
2017-01-03 11:00:40,658 INFO org.apache.hadoop.yarn.factories.impl.pb.RpcServerFactoryPBImpl: Adding protocol org.apache.hadoop.yarn.api.ApplicationClientProtocolPB to the server
2017-01-03 11:00:40,658 INFO org.apache.hadoop.ipc.Server: IPC Server Responder: starting
2017-01-03 11:00:40,659 INFO org.apache.hadoop.ipc.Server: IPC Server listener on 8032: starting
2017-01-03 11:00:40,666 INFO org.apache.hadoop.yarn.server.resourcemanager.ResourceManager: Transitioned to active state
2017-01-03 11:00:40,739 INFO org.mortbay.log: Logging to org.slf4j.impl.Log4jLoggerAdapter(org.mortbay.log) via org.mortbay.log.Slf4jLog
2017-01-03 11:00:40,746 INFO org.apache.hadoop.security.authentication.server.AuthenticationFilter: Unable to initialize FileSignerSecretProvider, falling back to use random secrets.
2017-01-03 11:00:40,752 INFO org.apache.hadoop.http.HttpRequestLog: Http request log for http.requests.resourcemanager is not defined
2017-01-03 11:00:40,760 INFO org.apache.hadoop.http.HttpServer2: Added global filter 'safety' (class=org.apache.hadoop.http.HttpServer2$QuotingInputFilter)
2017-01-03 11:00:40,763 INFO org.apache.hadoop.http.HttpServer2: Added filter RMAuthenticationFilter (class=org.apache.hadoop.yarn.server.security.http.RMAuthenticationFilter) to context cluster
2017-01-03 11:00:40,763 INFO org.apache.hadoop.http.HttpServer2: Added filter RMAuthenticationFilter (class=org.apache.hadoop.yarn.server.security.http.RMAuthenticationFilter) to context static
2017-01-03 11:00:40,763 INFO org.apache.hadoop.http.HttpServer2: Added filter RMAuthenticationFilter (class=org.apache.hadoop.yarn.server.security.http.RMAuthenticationFilter) to context logs
2017-01-03 11:00:40,764 INFO org.apache.hadoop.http.HttpServer2: Added filter static_user_filter (class=org.apache.hadoop.http.lib.StaticUserWebFilter$StaticUserFilter) to context cluster
2017-01-03 11:00:40,764 INFO org.apache.hadoop.http.HttpServer2: Added filter static_user_filter (class=org.apache.hadoop.http.lib.StaticUserWebFilter$StaticUserFilter) to context static
2017-01-03 11:00:40,764 INFO org.apache.hadoop.http.HttpServer2: Added filter static_user_filter (class=org.apache.hadoop.http.lib.StaticUserWebFilter$StaticUserFilter) to context logs
2017-01-03 11:00:40,767 INFO org.apache.hadoop.http.HttpServer2: adding path spec: /cluster/*
2017-01-03 11:00:40,768 INFO org.apache.hadoop.http.HttpServer2: adding path spec: /ws/*
2017-01-03 11:00:41,128 INFO org.apache.hadoop.yarn.webapp.WebApps: Registered webapp guice modules
2017-01-03 11:00:41,130 INFO org.apache.hadoop.http.HttpServer2: Jetty bound to port 8088
2017-01-03 11:00:41,130 INFO org.mortbay.log: jetty-6.1.26
2017-01-03 11:00:41,155 INFO org.mortbay.log: Extract jar:file:/usr/local/hadoop/share/hadoop/yarn/hadoop-yarn-common-2.7.3.jar!/webapps/cluster to /tmp/Jetty_Master_8088_cluster____v8ws0g/webapp
2017-01-03 11:00:41,315 INFO org.apache.hadoop.security.token.delegation.AbstractDelegationTokenSecretManager: Updating the current master key for generating delegation tokens
2017-01-03 11:00:41,315 INFO org.apache.hadoop.security.token.delegation.AbstractDelegationTokenSecretManager: Starting expired delegation token remover thread, tokenRemoverScanInterval=60 min(s)
2017-01-03 11:00:41,316 INFO org.apache.hadoop.security.token.delegation.AbstractDelegationTokenSecretManager: Updating the current master key for generating delegation tokens
2017-01-03 11:00:42,135 INFO org.mortbay.log: Started HttpServer2$SelectChannelConnectorWithSafeStartup@Master:8088
2017-01-03 11:00:42,135 INFO org.apache.hadoop.yarn.webapp.WebApps: Web app cluster started at 8088
2017-01-03 11:00:42,158 INFO org.apache.hadoop.ipc.CallQueueManager: Using callQueue class java.util.concurrent.LinkedBlockingQueue
2017-01-03 11:00:42,159 INFO org.apache.hadoop.ipc.Server: Starting Socket Reader #1 for port 8033
2017-01-03 11:00:42,160 INFO org.apache.hadoop.yarn.factories.impl.pb.RpcServerFactoryPBImpl: Adding protocol org.apache.hadoop.yarn.server.api.ResourceManagerAdministrationProtocolPB to the server
2017-01-03 11:00:42,162 INFO org.apache.hadoop.ipc.Server: IPC Server Responder: starting
2017-01-03 11:00:42,162 INFO org.apache.hadoop.ipc.Server: IPC Server listener on 8033: starting
2017-01-03 11:01:01,907 INFO org.apache.hadoop.yarn.server.resourcemanager.ResourceTrackerService: Node not found resyncing tfs04:38559
2017-01-03 11:01:01,907 INFO org.apache.hadoop.yarn.server.resourcemanager.ResourceTrackerService: Node not found resyncing tfs02:55092
2017-01-03 11:01:02,219 INFO org.apache.hadoop.yarn.server.resourcemanager.ResourceTrackerService: Node not found resyncing tfs03:45427
2017-01-03 11:01:02,953 INFO org.apache.hadoop.yarn.util.RackResolver: Resolved tfs02 to /default-rack
2017-01-03 11:01:02,953 INFO org.apache.hadoop.yarn.util.RackResolver: Resolved tfs04 to /default-rack
2017-01-03 11:01:02,959 INFO org.apache.hadoop.yarn.server.resourcemanager.ResourceTrackerService: NodeManager from node tfs02(cmPort: 55092 httpPort: 8042) registered with capability: <memory:8192, vCores:8>, assigned nodeId tfs02:55092
2017-01-03 11:01:02,961 INFO org.apache.hadoop.yarn.server.resourcemanager.ResourceTrackerService: NodeManager from node tfs04(cmPort: 38559 httpPort: 8042) registered with capability: <memory:8192, vCores:8>, assigned nodeId tfs04:38559
2017-01-03 11:01:02,969 INFO org.apache.hadoop.yarn.server.resourcemanager.rmnode.RMNodeImpl: tfs02:55092 Node Transitioned from NEW to RUNNING
2017-01-03 11:01:02,970 WARN org.apache.hadoop.yarn.server.resourcemanager.rmnode.RMNodeImpl: Cannot get RMApp by appId=application_1483411792436_0001, just added it to finishedApplications list for cleanup
2017-01-03 11:01:02,971 WARN org.apache.hadoop.yarn.server.resourcemanager.rmnode.RMNodeImpl: Cannot get RMApp by appId=application_1483411792436_0003, just added it to finishedApplications list for cleanup
2017-01-03 11:01:02,971 INFO org.apache.hadoop.yarn.server.resourcemanager.rmnode.RMNodeImpl: tfs04:38559 Node Transitioned from NEW to RUNNING
2017-01-03 11:01:02,972 INFO org.apache.hadoop.yarn.server.resourcemanager.rmnode.RMNodeImpl: Node tfs02:55092 reported UNHEALTHY with details: 1/1 local-dirs are bad: /usr/local/hadoop/tmp/nm-local-dir; 1/1 log-dirs are bad: /usr/local/hadoop/logs/userlogs
2017-01-03 11:01:02,974 INFO org.apache.hadoop.yarn.server.resourcemanager.rmnode.RMNodeImpl: tfs02:55092 Node Transitioned from RUNNING to UNHEALTHY
2017-01-03 11:01:02,978 INFO org.apache.hadoop.yarn.server.resourcemanager.scheduler.capacity.CapacityScheduler: Added node tfs02:55092 clusterResource: <memory:8192, vCores:8>
2017-01-03 11:01:02,979 INFO org.apache.hadoop.yarn.server.resourcemanager.scheduler.capacity.CapacityScheduler: Added node tfs04:38559 clusterResource: <memory:16384, vCores:16>
2017-01-03 11:01:02,980 INFO org.apache.hadoop.yarn.server.resourcemanager.scheduler.capacity.CapacityScheduler: Removed node tfs02:55092 clusterResource: <memory:8192, vCores:8>
2017-01-03 11:01:03,222 INFO org.apache.hadoop.yarn.util.RackResolver: Resolved tfs03 to /default-rack
2017-01-03 11:01:03,222 INFO org.apache.hadoop.yarn.server.resourcemanager.ResourceTrackerService: NodeManager from node tfs03(cmPort: 45427 httpPort: 8042) registered with capability: <memory:8192, vCores:8>, assigned nodeId tfs03:45427
2017-01-03 11:01:03,223 WARN org.apache.hadoop.yarn.server.resourcemanager.rmnode.RMNodeImpl: Cannot get RMApp by appId=application_1483411792436_0001, just added it to finishedApplications list for cleanup
2017-01-03 11:01:03,223 WARN org.apache.hadoop.yarn.server.resourcemanager.rmnode.RMNodeImpl: Cannot get RMApp by appId=application_1483411792436_0002, just added it to finishedApplications list for cleanup
2017-01-03 11:01:03,223 WARN org.apache.hadoop.yarn.server.resourcemanager.rmnode.RMNodeImpl: Cannot get RMApp by appId=application_1483411792436_0003, just added it to finishedApplications list for cleanup
2017-01-03 11:01:03,223 INFO org.apache.hadoop.yarn.server.resourcemanager.rmnode.RMNodeImpl: tfs03:45427 Node Transitioned from NEW to RUNNING
2017-01-03 11:01:03,224 INFO org.apache.hadoop.yarn.server.resourcemanager.scheduler.capacity.CapacityScheduler: Added node tfs03:45427 clusterResource: <memory:16384, vCores:16>
2017-01-03 11:01:19,047 INFO org.apache.hadoop.yarn.server.resourcemanager.ClientRMService: Allocated new applicationId: 1
2017-01-03 11:01:24,940 INFO org.apache.hadoop.yarn.server.resourcemanager.ClientRMService: Application with id 1 submitted by user root
2017-01-03 11:01:24,940 INFO org.apache.hadoop.yarn.server.resourcemanager.rmapp.RMAppImpl: Storing application with id application_1483412440498_0001
2017-01-03 11:01:24,943 INFO org.apache.hadoop.yarn.server.resourcemanager.RMAuditLogger: USER=root	IP=192.168.50.11	OPERATION=Submit Application Request	TARGET=ClientRMService	RESULT=SUCCESS	APPID=application_1483412440498_0001
2017-01-03 11:01:24,949 INFO org.apache.hadoop.yarn.server.resourcemanager.recovery.RMStateStore: Storing info for app: application_1483412440498_0001
2017-01-03 11:01:24,949 INFO org.apache.hadoop.yarn.server.resourcemanager.rmapp.RMAppImpl: application_1483412440498_0001 State change from NEW to NEW_SAVING
2017-01-03 11:01:24,950 INFO org.apache.hadoop.yarn.server.resourcemanager.rmapp.RMAppImpl: application_1483412440498_0001 State change from NEW_SAVING to SUBMITTED
2017-01-03 11:01:24,952 INFO org.apache.hadoop.yarn.server.resourcemanager.scheduler.capacity.ParentQueue: Application added - appId: application_1483412440498_0001 user: root leaf-queue of parent: root #applications: 1
2017-01-03 11:01:24,955 INFO org.apache.hadoop.yarn.server.resourcemanager.scheduler.capacity.CapacityScheduler: Accepted application application_1483412440498_0001 from user: root, in queue: default
2017-01-03 11:01:24,973 INFO org.apache.hadoop.yarn.server.resourcemanager.rmapp.RMAppImpl: application_1483412440498_0001 State change from SUBMITTED to ACCEPTED
2017-01-03 11:01:24,998 INFO org.apache.hadoop.yarn.server.resourcemanager.ApplicationMasterService: Registering app attempt : appattempt_1483412440498_0001_000001
2017-01-03 11:01:24,999 INFO org.apache.hadoop.yarn.server.resourcemanager.rmapp.attempt.RMAppAttemptImpl: appattempt_1483412440498_0001_000001 State change from NEW to SUBMITTED
2017-01-03 11:01:25,011 INFO org.apache.hadoop.yarn.server.resourcemanager.scheduler.capacity.LeafQueue: Application application_1483412440498_0001 from user: root activated in queue: default
2017-01-03 11:01:25,011 INFO org.apache.hadoop.yarn.server.resourcemanager.scheduler.capacity.LeafQueue: Application added - appId: application_1483412440498_0001 user: org.apache.hadoop.yarn.server.resourcemanager.scheduler.capacity.LeafQueue$User@5bc6df2c, leaf-queue: default #user-pending-applications: 0 #user-active-applications: 1 #queue-pending-applications: 0 #queue-active-applications: 1
2017-01-03 11:01:25,011 INFO org.apache.hadoop.yarn.server.resourcemanager.scheduler.capacity.CapacityScheduler: Added Application Attempt appattempt_1483412440498_0001_000001 to scheduler from user root in queue default
2017-01-03 11:01:25,013 INFO org.apache.hadoop.yarn.server.resourcemanager.rmapp.attempt.RMAppAttemptImpl: appattempt_1483412440498_0001_000001 State change from SUBMITTED to SCHEDULED
2017-01-03 11:01:25,040 INFO org.apache.hadoop.yarn.server.resourcemanager.rmcontainer.RMContainerImpl: container_1483412440498_0001_01_000001 Container Transitioned from NEW to ALLOCATED
2017-01-03 11:01:25,040 INFO org.apache.hadoop.yarn.server.resourcemanager.RMAuditLogger: USER=root	OPERATION=AM Allocated Container	TARGET=SchedulerApp	RESULT=SUCCESS	APPID=application_1483412440498_0001	CONTAINERID=container_1483412440498_0001_01_000001
2017-01-03 11:01:25,041 INFO org.apache.hadoop.yarn.server.resourcemanager.scheduler.SchedulerNode: Assigned container container_1483412440498_0001_01_000001 of capacity <memory:2048, vCores:1> on host tfs04:38559, which has 1 containers, <memory:2048, vCores:1> used and <memory:6144, vCores:7> available after allocation
2017-01-03 11:01:25,041 INFO org.apache.hadoop.yarn.server.resourcemanager.scheduler.capacity.LeafQueue: assignedContainer application attempt=appattempt_1483412440498_0001_000001 container=Container: [ContainerId: container_1483412440498_0001_01_000001, NodeId: tfs04:38559, NodeHttpAddress: tfs04:8042, Resource: <memory:2048, vCores:1>, Priority: 0, Token: null, ] queue=default: capacity=1.0, absoluteCapacity=1.0, usedResources=<memory:0, vCores:0>, usedCapacity=0.0, absoluteUsedCapacity=0.0, numApps=1, numContainers=0 clusterResource=<memory:16384, vCores:16> type=OFF_SWITCH
2017-01-03 11:01:25,041 INFO org.apache.hadoop.yarn.server.resourcemanager.scheduler.capacity.ParentQueue: Re-sorting assigned queue: root.default stats: default: capacity=1.0, absoluteCapacity=1.0, usedResources=<memory:2048, vCores:1>, usedCapacity=0.125, absoluteUsedCapacity=0.125, numApps=1, numContainers=1
2017-01-03 11:01:25,041 INFO org.apache.hadoop.yarn.server.resourcemanager.scheduler.capacity.ParentQueue: assignedContainer queue=root usedCapacity=0.125 absoluteUsedCapacity=0.125 used=<memory:2048, vCores:1> cluster=<memory:16384, vCores:16>
2017-01-03 11:01:25,057 INFO org.apache.hadoop.yarn.server.resourcemanager.security.NMTokenSecretManagerInRM: Sending NMToken for nodeId : tfs04:38559 for container : container_1483412440498_0001_01_000001
2017-01-03 11:01:25,066 INFO org.apache.hadoop.yarn.server.resourcemanager.rmcontainer.RMContainerImpl: container_1483412440498_0001_01_000001 Container Transitioned from ALLOCATED to ACQUIRED
2017-01-03 11:01:25,067 INFO org.apache.hadoop.yarn.server.resourcemanager.security.NMTokenSecretManagerInRM: Clear node set for appattempt_1483412440498_0001_000001
2017-01-03 11:01:25,070 INFO org.apache.hadoop.yarn.server.resourcemanager.rmapp.attempt.RMAppAttemptImpl: Storing attempt: AppId: application_1483412440498_0001 AttemptId: appattempt_1483412440498_0001_000001 MasterContainer: Container: [ContainerId: container_1483412440498_0001_01_000001, NodeId: tfs04:38559, NodeHttpAddress: tfs04:8042, Resource: <memory:2048, vCores:1>, Priority: 0, Token: Token { kind: ContainerToken, service: 192.168.50.14:38559 }, ]
2017-01-03 11:01:25,081 INFO org.apache.hadoop.yarn.server.resourcemanager.rmapp.attempt.RMAppAttemptImpl: appattempt_1483412440498_0001_000001 State change from SCHEDULED to ALLOCATED_SAVING
2017-01-03 11:01:25,082 INFO org.apache.hadoop.yarn.server.resourcemanager.rmapp.attempt.RMAppAttemptImpl: appattempt_1483412440498_0001_000001 State change from ALLOCATED_SAVING to ALLOCATED
2017-01-03 11:01:25,085 INFO org.apache.hadoop.yarn.server.resourcemanager.amlauncher.AMLauncher: Launching masterappattempt_1483412440498_0001_000001
2017-01-03 11:01:25,119 INFO org.apache.hadoop.yarn.server.resourcemanager.amlauncher.AMLauncher: Setting up container Container: [ContainerId: container_1483412440498_0001_01_000001, NodeId: tfs04:38559, NodeHttpAddress: tfs04:8042, Resource: <memory:2048, vCores:1>, Priority: 0, Token: Token { kind: ContainerToken, service: 192.168.50.14:38559 }, ] for AM appattempt_1483412440498_0001_000001
2017-01-03 11:01:25,119 INFO org.apache.hadoop.yarn.server.resourcemanager.amlauncher.AMLauncher: Command to launch container container_1483412440498_0001_01_000001 : $JAVA_HOME/bin/java -Djava.io.tmpdir=$PWD/tmp -Dlog4j.configuration=container-log4j.properties -Dyarn.app.container.log.dir=<LOG_DIR> -Dyarn.app.container.log.filesize=0 -Dhadoop.root.logger=INFO,CLA -Dhadoop.root.logfile=syslog  -Xmx1024m org.apache.hadoop.mapreduce.v2.app.MRAppMaster 1><LOG_DIR>/stdout 2><LOG_DIR>/stderr 
2017-01-03 11:01:25,121 INFO org.apache.hadoop.yarn.server.resourcemanager.security.AMRMTokenSecretManager: Create AMRMToken for ApplicationAttempt: appattempt_1483412440498_0001_000001
2017-01-03 11:01:25,124 INFO org.apache.hadoop.yarn.server.resourcemanager.security.AMRMTokenSecretManager: Creating password for appattempt_1483412440498_0001_000001
2017-01-03 11:01:25,226 INFO org.apache.hadoop.yarn.server.resourcemanager.amlauncher.AMLauncher: Done launching container Container: [ContainerId: container_1483412440498_0001_01_000001, NodeId: tfs04:38559, NodeHttpAddress: tfs04:8042, Resource: <memory:2048, vCores:1>, Priority: 0, Token: Token { kind: ContainerToken, service: 192.168.50.14:38559 }, ] for AM appattempt_1483412440498_0001_000001
2017-01-03 11:01:25,226 INFO org.apache.hadoop.yarn.server.resourcemanager.rmapp.attempt.RMAppAttemptImpl: appattempt_1483412440498_0001_000001 State change from ALLOCATED to LAUNCHED
2017-01-03 11:01:26,031 INFO org.apache.hadoop.yarn.server.resourcemanager.rmcontainer.RMContainerImpl: container_1483412440498_0001_01_000001 Container Transitioned from ACQUIRED to RUNNING
2017-01-03 11:01:33,519 INFO SecurityLogger.org.apache.hadoop.ipc.Server: Auth successful for appattempt_1483412440498_0001_000001 (auth:SIMPLE)
2017-01-03 11:01:33,536 INFO org.apache.hadoop.yarn.server.resourcemanager.ApplicationMasterService: AM registration appattempt_1483412440498_0001_000001
2017-01-03 11:01:33,537 INFO org.apache.hadoop.yarn.server.resourcemanager.RMAuditLogger: USER=root	IP=192.168.50.14	OPERATION=Register App Master	TARGET=ApplicationMasterService	RESULT=SUCCESS	APPID=application_1483412440498_0001	APPATTEMPTID=appattempt_1483412440498_0001_000001
2017-01-03 11:01:33,538 INFO org.apache.hadoop.yarn.server.resourcemanager.rmapp.attempt.RMAppAttemptImpl: appattempt_1483412440498_0001_000001 State change from LAUNCHED to RUNNING
2017-01-03 11:01:33,538 INFO org.apache.hadoop.yarn.server.resourcemanager.rmapp.RMAppImpl: application_1483412440498_0001 State change from ACCEPTED to RUNNING
2017-01-03 11:01:35,292 INFO org.apache.hadoop.yarn.server.resourcemanager.rmcontainer.RMContainerImpl: container_1483412440498_0001_01_000002 Container Transitioned from NEW to ALLOCATED
2017-01-03 11:01:35,292 INFO org.apache.hadoop.yarn.server.resourcemanager.RMAuditLogger: USER=root	OPERATION=AM Allocated Container	TARGET=SchedulerApp	RESULT=SUCCESS	APPID=application_1483412440498_0001	CONTAINERID=container_1483412440498_0001_01_000002
2017-01-03 11:01:35,292 INFO org.apache.hadoop.yarn.server.resourcemanager.scheduler.SchedulerNode: Assigned container container_1483412440498_0001_01_000002 of capacity <memory:1024, vCores:1> on host tfs03:45427, which has 1 containers, <memory:1024, vCores:1> used and <memory:7168, vCores:7> available after allocation
2017-01-03 11:01:35,292 INFO org.apache.hadoop.yarn.server.resourcemanager.scheduler.capacity.LeafQueue: assignedContainer application attempt=appattempt_1483412440498_0001_000001 container=Container: [ContainerId: container_1483412440498_0001_01_000002, NodeId: tfs03:45427, NodeHttpAddress: tfs03:8042, Resource: <memory:1024, vCores:1>, Priority: 20, Token: null, ] queue=default: capacity=1.0, absoluteCapacity=1.0, usedResources=<memory:2048, vCores:1>, usedCapacity=0.125, absoluteUsedCapacity=0.125, numApps=1, numContainers=1 clusterResource=<memory:16384, vCores:16> type=NODE_LOCAL
2017-01-03 11:01:35,293 INFO org.apache.hadoop.yarn.server.resourcemanager.scheduler.capacity.ParentQueue: Re-sorting assigned queue: root.default stats: default: capacity=1.0, absoluteCapacity=1.0, usedResources=<memory:3072, vCores:2>, usedCapacity=0.1875, absoluteUsedCapacity=0.1875, numApps=1, numContainers=2
2017-01-03 11:01:35,293 INFO org.apache.hadoop.yarn.server.resourcemanager.scheduler.capacity.ParentQueue: assignedContainer queue=root usedCapacity=0.1875 absoluteUsedCapacity=0.1875 used=<memory:3072, vCores:2> cluster=<memory:16384, vCores:16>
2017-01-03 11:01:35,631 INFO org.apache.hadoop.yarn.server.resourcemanager.security.NMTokenSecretManagerInRM: Sending NMToken for nodeId : tfs03:45427 for container : container_1483412440498_0001_01_000002
2017-01-03 11:01:35,635 INFO org.apache.hadoop.yarn.server.resourcemanager.rmcontainer.RMContainerImpl: container_1483412440498_0001_01_000002 Container Transitioned from ALLOCATED to ACQUIRED
2017-01-03 11:01:36,047 INFO org.apache.hadoop.yarn.server.resourcemanager.rmcontainer.RMContainerImpl: container_1483412440498_0001_01_000003 Container Transitioned from NEW to ALLOCATED
2017-01-03 11:01:36,049 INFO org.apache.hadoop.yarn.server.resourcemanager.RMAuditLogger: USER=root	OPERATION=AM Allocated Container	TARGET=SchedulerApp	RESULT=SUCCESS	APPID=application_1483412440498_0001	CONTAINERID=container_1483412440498_0001_01_000003
2017-01-03 11:01:36,049 INFO org.apache.hadoop.yarn.server.resourcemanager.scheduler.SchedulerNode: Assigned container container_1483412440498_0001_01_000003 of capacity <memory:1024, vCores:1> on host tfs04:38559, which has 2 containers, <memory:3072, vCores:2> used and <memory:5120, vCores:6> available after allocation
2017-01-03 11:01:36,049 INFO org.apache.hadoop.yarn.server.resourcemanager.scheduler.capacity.LeafQueue: assignedContainer application attempt=appattempt_1483412440498_0001_000001 container=Container: [ContainerId: container_1483412440498_0001_01_000003, NodeId: tfs04:38559, NodeHttpAddress: tfs04:8042, Resource: <memory:1024, vCores:1>, Priority: 20, Token: null, ] queue=default: capacity=1.0, absoluteCapacity=1.0, usedResources=<memory:3072, vCores:2>, usedCapacity=0.1875, absoluteUsedCapacity=0.1875, numApps=1, numContainers=2 clusterResource=<memory:16384, vCores:16> type=OFF_SWITCH
2017-01-03 11:01:36,049 INFO org.apache.hadoop.yarn.server.resourcemanager.scheduler.capacity.ParentQueue: Re-sorting assigned queue: root.default stats: default: capacity=1.0, absoluteCapacity=1.0, usedResources=<memory:4096, vCores:3>, usedCapacity=0.25, absoluteUsedCapacity=0.25, numApps=1, numContainers=3
2017-01-03 11:01:36,049 INFO org.apache.hadoop.yarn.server.resourcemanager.scheduler.capacity.ParentQueue: assignedContainer queue=root usedCapacity=0.25 absoluteUsedCapacity=0.25 used=<memory:4096, vCores:3> cluster=<memory:16384, vCores:16>
2017-01-03 11:01:36,701 INFO org.apache.hadoop.yarn.server.resourcemanager.security.NMTokenSecretManagerInRM: Sending NMToken for nodeId : tfs04:38559 for container : container_1483412440498_0001_01_000003
2017-01-03 11:01:36,708 INFO org.apache.hadoop.yarn.server.resourcemanager.rmcontainer.RMContainerImpl: container_1483412440498_0001_01_000003 Container Transitioned from ALLOCATED to ACQUIRED
2017-01-03 11:01:37,049 INFO org.apache.hadoop.yarn.server.resourcemanager.rmcontainer.RMContainerImpl: container_1483412440498_0001_01_000003 Container Transitioned from ACQUIRED to RUNNING
2017-01-03 11:01:37,051 INFO org.apache.hadoop.yarn.server.resourcemanager.rmcontainer.RMContainerImpl: container_1483412440498_0001_01_000004 Container Transitioned from NEW to ALLOCATED
2017-01-03 11:01:37,051 INFO org.apache.hadoop.yarn.server.resourcemanager.RMAuditLogger: USER=root	OPERATION=AM Allocated Container	TARGET=SchedulerApp	RESULT=SUCCESS	APPID=application_1483412440498_0001	CONTAINERID=container_1483412440498_0001_01_000004
2017-01-03 11:01:37,051 INFO org.apache.hadoop.yarn.server.resourcemanager.scheduler.SchedulerNode: Assigned container container_1483412440498_0001_01_000004 of capacity <memory:1024, vCores:1> on host tfs04:38559, which has 3 containers, <memory:4096, vCores:3> used and <memory:4096, vCores:5> available after allocation
2017-01-03 11:01:37,052 INFO org.apache.hadoop.yarn.server.resourcemanager.scheduler.capacity.LeafQueue: assignedContainer application attempt=appattempt_1483412440498_0001_000001 container=Container: [ContainerId: container_1483412440498_0001_01_000004, NodeId: tfs04:38559, NodeHttpAddress: tfs04:8042, Resource: <memory:1024, vCores:1>, Priority: 20, Token: null, ] queue=default: capacity=1.0, absoluteCapacity=1.0, usedResources=<memory:4096, vCores:3>, usedCapacity=0.25, absoluteUsedCapacity=0.25, numApps=1, numContainers=3 clusterResource=<memory:16384, vCores:16> type=RACK_LOCAL
2017-01-03 11:01:37,052 INFO org.apache.hadoop.yarn.server.resourcemanager.scheduler.capacity.ParentQueue: Re-sorting assigned queue: root.default stats: default: capacity=1.0, absoluteCapacity=1.0, usedResources=<memory:5120, vCores:4>, usedCapacity=0.3125, absoluteUsedCapacity=0.3125, numApps=1, numContainers=4
2017-01-03 11:01:37,052 INFO org.apache.hadoop.yarn.server.resourcemanager.scheduler.capacity.ParentQueue: assignedContainer queue=root usedCapacity=0.3125 absoluteUsedCapacity=0.3125 used=<memory:5120, vCores:4> cluster=<memory:16384, vCores:16>
2017-01-03 11:01:37,296 INFO org.apache.hadoop.yarn.server.resourcemanager.rmcontainer.RMContainerImpl: container_1483412440498_0001_01_000002 Container Transitioned from ACQUIRED to RUNNING
2017-01-03 11:01:37,716 INFO org.apache.hadoop.yarn.server.resourcemanager.scheduler.AppSchedulingInfo: checking for deactivate of application :application_1483412440498_0001
2017-01-03 11:01:37,723 INFO org.apache.hadoop.yarn.server.resourcemanager.rmcontainer.RMContainerImpl: container_1483412440498_0001_01_000004 Container Transitioned from ALLOCATED to ACQUIRED
2017-01-03 11:01:38,733 INFO org.apache.hadoop.yarn.server.resourcemanager.rmcontainer.RMContainerImpl: container_1483412440498_0001_01_000004 Container Transitioned from ACQUIRED to RELEASED
2017-01-03 11:01:38,733 INFO org.apache.hadoop.yarn.server.resourcemanager.scheduler.common.fica.FiCaSchedulerApp: Completed container: container_1483412440498_0001_01_000004 in state: RELEASED event:RELEASED
2017-01-03 11:01:38,734 INFO org.apache.hadoop.yarn.server.resourcemanager.RMAuditLogger: USER=root	IP=192.168.50.14	OPERATION=AM Released Container	TARGET=SchedulerApp	RESULT=SUCCESS	APPID=application_1483412440498_0001	CONTAINERID=container_1483412440498_0001_01_000004
2017-01-03 11:01:38,734 INFO org.apache.hadoop.yarn.server.resourcemanager.scheduler.SchedulerNode: Released container container_1483412440498_0001_01_000004 of capacity <memory:1024, vCores:1> on host tfs04:38559, which currently has 2 containers, <memory:3072, vCores:2> used and <memory:5120, vCores:6> available, release resources=true
2017-01-03 11:01:38,735 INFO org.apache.hadoop.yarn.server.resourcemanager.scheduler.capacity.LeafQueue: default used=<memory:4096, vCores:3> numContainers=3 user=root user-resources=<memory:4096, vCores:3>
2017-01-03 11:01:38,736 INFO org.apache.hadoop.yarn.server.resourcemanager.scheduler.capacity.LeafQueue: completedContainer container=Container: [ContainerId: container_1483412440498_0001_01_000004, NodeId: tfs04:38559, NodeHttpAddress: tfs04:8042, Resource: <memory:1024, vCores:1>, Priority: 20, Token: Token { kind: ContainerToken, service: 192.168.50.14:38559 }, ] queue=default: capacity=1.0, absoluteCapacity=1.0, usedResources=<memory:4096, vCores:3>, usedCapacity=0.25, absoluteUsedCapacity=0.25, numApps=1, numContainers=3 cluster=<memory:16384, vCores:16>
2017-01-03 11:01:38,736 INFO org.apache.hadoop.yarn.server.resourcemanager.scheduler.capacity.ParentQueue: completedContainer queue=root usedCapacity=0.25 absoluteUsedCapacity=0.25 used=<memory:4096, vCores:3> cluster=<memory:16384, vCores:16>
2017-01-03 11:01:38,737 INFO org.apache.hadoop.yarn.server.resourcemanager.scheduler.capacity.ParentQueue: Re-sorting completed queue: root.default stats: default: capacity=1.0, absoluteCapacity=1.0, usedResources=<memory:4096, vCores:3>, usedCapacity=0.25, absoluteUsedCapacity=0.25, numApps=1, numContainers=3
2017-01-03 11:01:38,737 INFO org.apache.hadoop.yarn.server.resourcemanager.scheduler.capacity.CapacityScheduler: Application attempt appattempt_1483412440498_0001_000001 released container container_1483412440498_0001_01_000004 on node: host: tfs04:38559 #containers=2 available=<memory:5120, vCores:6> used=<memory:3072, vCores:2> with event: RELEASED
2017-01-03 11:01:45,244 INFO org.apache.hadoop.yarn.server.resourcemanager.rmcontainer.RMContainerImpl: container_1483412440498_0001_01_000003 Container Transitioned from RUNNING to COMPLETED
2017-01-03 11:01:45,245 INFO org.apache.hadoop.yarn.server.resourcemanager.scheduler.common.fica.FiCaSchedulerApp: Completed container: container_1483412440498_0001_01_000003 in state: COMPLETED event:FINISHED
2017-01-03 11:01:45,245 INFO org.apache.hadoop.yarn.server.resourcemanager.RMAuditLogger: USER=root	OPERATION=AM Released Container	TARGET=SchedulerApp	RESULT=SUCCESS	APPID=application_1483412440498_0001	CONTAINERID=container_1483412440498_0001_01_000003
2017-01-03 11:01:45,246 INFO org.apache.hadoop.yarn.server.resourcemanager.scheduler.SchedulerNode: Released container container_1483412440498_0001_01_000003 of capacity <memory:1024, vCores:1> on host tfs04:38559, which currently has 1 containers, <memory:2048, vCores:1> used and <memory:6144, vCores:7> available, release resources=true
2017-01-03 11:01:45,246 INFO org.apache.hadoop.yarn.server.resourcemanager.scheduler.capacity.LeafQueue: default used=<memory:3072, vCores:2> numContainers=2 user=root user-resources=<memory:3072, vCores:2>
2017-01-03 11:01:45,246 INFO org.apache.hadoop.yarn.server.resourcemanager.scheduler.capacity.LeafQueue: completedContainer container=Container: [ContainerId: container_1483412440498_0001_01_000003, NodeId: tfs04:38559, NodeHttpAddress: tfs04:8042, Resource: <memory:1024, vCores:1>, Priority: 20, Token: Token { kind: ContainerToken, service: 192.168.50.14:38559 }, ] queue=default: capacity=1.0, absoluteCapacity=1.0, usedResources=<memory:3072, vCores:2>, usedCapacity=0.1875, absoluteUsedCapacity=0.1875, numApps=1, numContainers=2 cluster=<memory:16384, vCores:16>
2017-01-03 11:01:45,247 INFO org.apache.hadoop.yarn.server.resourcemanager.scheduler.capacity.ParentQueue: completedContainer queue=root usedCapacity=0.1875 absoluteUsedCapacity=0.1875 used=<memory:3072, vCores:2> cluster=<memory:16384, vCores:16>
2017-01-03 11:01:45,247 INFO org.apache.hadoop.yarn.server.resourcemanager.scheduler.capacity.ParentQueue: Re-sorting completed queue: root.default stats: default: capacity=1.0, absoluteCapacity=1.0, usedResources=<memory:3072, vCores:2>, usedCapacity=0.1875, absoluteUsedCapacity=0.1875, numApps=1, numContainers=2
2017-01-03 11:01:45,247 INFO org.apache.hadoop.yarn.server.resourcemanager.scheduler.capacity.CapacityScheduler: Application attempt appattempt_1483412440498_0001_000001 released container container_1483412440498_0001_01_000003 on node: host: tfs04:38559 #containers=1 available=<memory:6144, vCores:7> used=<memory:2048, vCores:1> with event: FINISHED
2017-01-03 11:01:46,550 INFO org.apache.hadoop.yarn.server.resourcemanager.rmcontainer.RMContainerImpl: container_1483412440498_0001_01_000002 Container Transitioned from RUNNING to COMPLETED
2017-01-03 11:01:46,550 INFO org.apache.hadoop.yarn.server.resourcemanager.scheduler.common.fica.FiCaSchedulerApp: Completed container: container_1483412440498_0001_01_000002 in state: COMPLETED event:FINISHED
2017-01-03 11:01:46,550 INFO org.apache.hadoop.yarn.server.resourcemanager.RMAuditLogger: USER=root	OPERATION=AM Released Container	TARGET=SchedulerApp	RESULT=SUCCESS	APPID=application_1483412440498_0001	CONTAINERID=container_1483412440498_0001_01_000002
2017-01-03 11:01:46,550 INFO org.apache.hadoop.yarn.server.resourcemanager.scheduler.SchedulerNode: Released container container_1483412440498_0001_01_000002 of capacity <memory:1024, vCores:1> on host tfs03:45427, which currently has 0 containers, <memory:0, vCores:0> used and <memory:8192, vCores:8> available, release resources=true
2017-01-03 11:01:46,550 INFO org.apache.hadoop.yarn.server.resourcemanager.scheduler.capacity.LeafQueue: default used=<memory:2048, vCores:1> numContainers=1 user=root user-resources=<memory:2048, vCores:1>
2017-01-03 11:01:46,551 INFO org.apache.hadoop.yarn.server.resourcemanager.scheduler.capacity.LeafQueue: completedContainer container=Container: [ContainerId: container_1483412440498_0001_01_000002, NodeId: tfs03:45427, NodeHttpAddress: tfs03:8042, Resource: <memory:1024, vCores:1>, Priority: 20, Token: Token { kind: ContainerToken, service: 192.168.50.13:45427 }, ] queue=default: capacity=1.0, absoluteCapacity=1.0, usedResources=<memory:2048, vCores:1>, usedCapacity=0.125, absoluteUsedCapacity=0.125, numApps=1, numContainers=1 cluster=<memory:16384, vCores:16>
2017-01-03 11:01:46,551 INFO org.apache.hadoop.yarn.server.resourcemanager.scheduler.capacity.ParentQueue: completedContainer queue=root usedCapacity=0.125 absoluteUsedCapacity=0.125 used=<memory:2048, vCores:1> cluster=<memory:16384, vCores:16>
2017-01-03 11:01:46,552 INFO org.apache.hadoop.yarn.server.resourcemanager.scheduler.capacity.ParentQueue: Re-sorting completed queue: root.default stats: default: capacity=1.0, absoluteCapacity=1.0, usedResources=<memory:2048, vCores:1>, usedCapacity=0.125, absoluteUsedCapacity=0.125, numApps=1, numContainers=1
2017-01-03 11:01:46,552 INFO org.apache.hadoop.yarn.server.resourcemanager.scheduler.capacity.CapacityScheduler: Application attempt appattempt_1483412440498_0001_000001 released container container_1483412440498_0001_01_000002 on node: host: tfs03:45427 #containers=0 available=<memory:8192, vCores:8> used=<memory:0, vCores:0> with event: FINISHED
2017-01-03 11:01:46,771 INFO org.apache.hadoop.yarn.server.resourcemanager.scheduler.AppSchedulingInfo: checking for deactivate of application :application_1483412440498_0001
2017-01-03 11:01:47,250 INFO org.apache.hadoop.yarn.server.resourcemanager.rmcontainer.RMContainerImpl: container_1483412440498_0001_01_000005 Container Transitioned from NEW to ALLOCATED
2017-01-03 11:01:47,250 INFO org.apache.hadoop.yarn.server.resourcemanager.RMAuditLogger: USER=root	OPERATION=AM Allocated Container	TARGET=SchedulerApp	RESULT=SUCCESS	APPID=application_1483412440498_0001	CONTAINERID=container_1483412440498_0001_01_000005
2017-01-03 11:01:47,250 INFO org.apache.hadoop.yarn.server.resourcemanager.scheduler.SchedulerNode: Assigned container container_1483412440498_0001_01_000005 of capacity <memory:1024, vCores:1> on host tfs04:38559, which has 2 containers, <memory:3072, vCores:2> used and <memory:5120, vCores:6> available after allocation
2017-01-03 11:01:47,250 INFO org.apache.hadoop.yarn.server.resourcemanager.scheduler.capacity.LeafQueue: assignedContainer application attempt=appattempt_1483412440498_0001_000001 container=Container: [ContainerId: container_1483412440498_0001_01_000005, NodeId: tfs04:38559, NodeHttpAddress: tfs04:8042, Resource: <memory:1024, vCores:1>, Priority: 10, Token: null, ] queue=default: capacity=1.0, absoluteCapacity=1.0, usedResources=<memory:2048, vCores:1>, usedCapacity=0.125, absoluteUsedCapacity=0.125, numApps=1, numContainers=1 clusterResource=<memory:16384, vCores:16> type=OFF_SWITCH
2017-01-03 11:01:47,251 INFO org.apache.hadoop.yarn.server.resourcemanager.scheduler.capacity.ParentQueue: Re-sorting assigned queue: root.default stats: default: capacity=1.0, absoluteCapacity=1.0, usedResources=<memory:3072, vCores:2>, usedCapacity=0.1875, absoluteUsedCapacity=0.1875, numApps=1, numContainers=2
2017-01-03 11:01:47,251 INFO org.apache.hadoop.yarn.server.resourcemanager.scheduler.capacity.ParentQueue: assignedContainer queue=root usedCapacity=0.1875 absoluteUsedCapacity=0.1875 used=<memory:3072, vCores:2> cluster=<memory:16384, vCores:16>
2017-01-03 11:01:47,779 INFO org.apache.hadoop.yarn.server.resourcemanager.rmcontainer.RMContainerImpl: container_1483412440498_0001_01_000005 Container Transitioned from ALLOCATED to ACQUIRED
2017-01-03 11:01:48,251 INFO org.apache.hadoop.yarn.server.resourcemanager.rmcontainer.RMContainerImpl: container_1483412440498_0001_01_000005 Container Transitioned from ACQUIRED to RUNNING
2017-01-03 11:01:48,786 INFO org.apache.hadoop.yarn.server.resourcemanager.scheduler.AppSchedulingInfo: checking for deactivate of application :application_1483412440498_0001
2017-01-03 11:01:51,504 INFO org.apache.hadoop.yarn.server.resourcemanager.rmcontainer.RMContainerImpl: container_1483412440498_0001_01_000005 Container Transitioned from RUNNING to COMPLETED
2017-01-03 11:01:51,504 INFO org.apache.hadoop.yarn.server.resourcemanager.scheduler.common.fica.FiCaSchedulerApp: Completed container: container_1483412440498_0001_01_000005 in state: COMPLETED event:FINISHED
2017-01-03 11:01:51,505 INFO org.apache.hadoop.yarn.server.resourcemanager.RMAuditLogger: USER=root	OPERATION=AM Released Container	TARGET=SchedulerApp	RESULT=SUCCESS	APPID=application_1483412440498_0001	CONTAINERID=container_1483412440498_0001_01_000005
2017-01-03 11:01:51,505 INFO org.apache.hadoop.yarn.server.resourcemanager.scheduler.SchedulerNode: Released container container_1483412440498_0001_01_000005 of capacity <memory:1024, vCores:1> on host tfs04:38559, which currently has 1 containers, <memory:2048, vCores:1> used and <memory:6144, vCores:7> available, release resources=true
2017-01-03 11:01:51,505 INFO org.apache.hadoop.yarn.server.resourcemanager.scheduler.capacity.LeafQueue: default used=<memory:2048, vCores:1> numContainers=1 user=root user-resources=<memory:2048, vCores:1>
2017-01-03 11:01:51,507 INFO org.apache.hadoop.yarn.server.resourcemanager.scheduler.capacity.LeafQueue: completedContainer container=Container: [ContainerId: container_1483412440498_0001_01_000005, NodeId: tfs04:38559, NodeHttpAddress: tfs04:8042, Resource: <memory:1024, vCores:1>, Priority: 10, Token: Token { kind: ContainerToken, service: 192.168.50.14:38559 }, ] queue=default: capacity=1.0, absoluteCapacity=1.0, usedResources=<memory:2048, vCores:1>, usedCapacity=0.125, absoluteUsedCapacity=0.125, numApps=1, numContainers=1 cluster=<memory:16384, vCores:16>
2017-01-03 11:01:51,507 INFO org.apache.hadoop.yarn.server.resourcemanager.scheduler.capacity.ParentQueue: completedContainer queue=root usedCapacity=0.125 absoluteUsedCapacity=0.125 used=<memory:2048, vCores:1> cluster=<memory:16384, vCores:16>
2017-01-03 11:01:51,507 INFO org.apache.hadoop.yarn.server.resourcemanager.scheduler.capacity.ParentQueue: Re-sorting completed queue: root.default stats: default: capacity=1.0, absoluteCapacity=1.0, usedResources=<memory:2048, vCores:1>, usedCapacity=0.125, absoluteUsedCapacity=0.125, numApps=1, numContainers=1
2017-01-03 11:01:51,507 INFO org.apache.hadoop.yarn.server.resourcemanager.scheduler.capacity.CapacityScheduler: Application attempt appattempt_1483412440498_0001_000001 released container container_1483412440498_0001_01_000005 on node: host: tfs04:38559 #containers=1 available=<memory:6144, vCores:7> used=<memory:2048, vCores:1> with event: FINISHED
2017-01-03 11:01:51,637 INFO org.apache.hadoop.yarn.server.resourcemanager.rmapp.attempt.RMAppAttemptImpl: Updating application attempt appattempt_1483412440498_0001_000001 with final state: FINISHING, and exit status: -1000
2017-01-03 11:01:51,638 INFO org.apache.hadoop.yarn.server.resourcemanager.rmapp.attempt.RMAppAttemptImpl: appattempt_1483412440498_0001_000001 State change from RUNNING to FINAL_SAVING
2017-01-03 11:01:51,639 INFO org.apache.hadoop.yarn.server.resourcemanager.rmapp.RMAppImpl: Updating application application_1483412440498_0001 with final state: FINISHING
2017-01-03 11:01:51,639 INFO org.apache.hadoop.yarn.server.resourcemanager.rmapp.RMAppImpl: application_1483412440498_0001 State change from RUNNING to FINAL_SAVING
2017-01-03 11:01:51,639 INFO org.apache.hadoop.yarn.server.resourcemanager.recovery.RMStateStore: Updating info for app: application_1483412440498_0001
2017-01-03 11:01:51,639 INFO org.apache.hadoop.yarn.server.resourcemanager.rmapp.attempt.RMAppAttemptImpl: appattempt_1483412440498_0001_000001 State change from FINAL_SAVING to FINISHING
2017-01-03 11:01:51,640 INFO org.apache.hadoop.yarn.server.resourcemanager.rmapp.RMAppImpl: application_1483412440498_0001 State change from FINAL_SAVING to FINISHING
2017-01-03 11:01:52,643 INFO org.apache.hadoop.yarn.server.resourcemanager.ApplicationMasterService: application_1483412440498_0001 unregistered successfully. 
2017-01-03 11:01:58,178 INFO org.apache.hadoop.yarn.server.resourcemanager.rmcontainer.RMContainerImpl: container_1483412440498_0001_01_000001 Container Transitioned from RUNNING to COMPLETED
2017-01-03 11:01:58,178 INFO org.apache.hadoop.yarn.server.resourcemanager.scheduler.common.fica.FiCaSchedulerApp: Completed container: container_1483412440498_0001_01_000001 in state: COMPLETED event:FINISHED
2017-01-03 11:01:58,178 INFO org.apache.hadoop.yarn.server.resourcemanager.ApplicationMasterService: Unregistering app attempt : appattempt_1483412440498_0001_000001
2017-01-03 11:01:58,178 INFO org.apache.hadoop.yarn.server.resourcemanager.RMAuditLogger: USER=root	OPERATION=AM Released Container	TARGET=SchedulerApp	RESULT=SUCCESS	APPID=application_1483412440498_0001	CONTAINERID=container_1483412440498_0001_01_000001
2017-01-03 11:01:58,179 INFO org.apache.hadoop.yarn.server.resourcemanager.scheduler.SchedulerNode: Released container container_1483412440498_0001_01_000001 of capacity <memory:2048, vCores:1> on host tfs04:38559, which currently has 0 containers, <memory:0, vCores:0> used and <memory:8192, vCores:8> available, release resources=true
2017-01-03 11:01:58,179 INFO org.apache.hadoop.yarn.server.resourcemanager.scheduler.capacity.LeafQueue: default used=<memory:0, vCores:0> numContainers=0 user=root user-resources=<memory:0, vCores:0>
2017-01-03 11:01:58,179 INFO org.apache.hadoop.yarn.server.resourcemanager.scheduler.capacity.LeafQueue: completedContainer container=Container: [ContainerId: container_1483412440498_0001_01_000001, NodeId: tfs04:38559, NodeHttpAddress: tfs04:8042, Resource: <memory:2048, vCores:1>, Priority: 0, Token: Token { kind: ContainerToken, service: 192.168.50.14:38559 }, ] queue=default: capacity=1.0, absoluteCapacity=1.0, usedResources=<memory:0, vCores:0>, usedCapacity=0.0, absoluteUsedCapacity=0.0, numApps=1, numContainers=0 cluster=<memory:16384, vCores:16>
2017-01-03 11:01:58,179 INFO org.apache.hadoop.yarn.server.resourcemanager.scheduler.capacity.ParentQueue: completedContainer queue=root usedCapacity=0.0 absoluteUsedCapacity=0.0 used=<memory:0, vCores:0> cluster=<memory:16384, vCores:16>
2017-01-03 11:01:58,179 INFO org.apache.hadoop.yarn.server.resourcemanager.scheduler.capacity.ParentQueue: Re-sorting completed queue: root.default stats: default: capacity=1.0, absoluteCapacity=1.0, usedResources=<memory:0, vCores:0>, usedCapacity=0.0, absoluteUsedCapacity=0.0, numApps=1, numContainers=0
2017-01-03 11:01:58,180 INFO org.apache.hadoop.yarn.server.resourcemanager.scheduler.capacity.CapacityScheduler: Application attempt appattempt_1483412440498_0001_000001 released container container_1483412440498_0001_01_000001 on node: host: tfs04:38559 #containers=0 available=<memory:8192, vCores:8> used=<memory:0, vCores:0> with event: FINISHED
2017-01-03 11:01:58,180 INFO org.apache.hadoop.yarn.server.resourcemanager.security.AMRMTokenSecretManager: Application finished, removing password for appattempt_1483412440498_0001_000001
2017-01-03 11:01:58,181 INFO org.apache.hadoop.yarn.server.resourcemanager.rmapp.attempt.RMAppAttemptImpl: appattempt_1483412440498_0001_000001 State change from FINISHING to FINISHED
2017-01-03 11:01:58,184 INFO org.apache.hadoop.yarn.server.resourcemanager.rmapp.RMAppImpl: application_1483412440498_0001 State change from FINISHING to FINISHED
2017-01-03 11:01:58,185 INFO org.apache.hadoop.yarn.server.resourcemanager.scheduler.capacity.CapacityScheduler: Application Attempt appattempt_1483412440498_0001_000001 is done. finalState=FINISHED
2017-01-03 11:01:58,185 INFO org.apache.hadoop.yarn.server.resourcemanager.scheduler.AppSchedulingInfo: Application application_1483412440498_0001 requests cleared
2017-01-03 11:01:58,185 INFO org.apache.hadoop.yarn.server.resourcemanager.scheduler.capacity.LeafQueue: Application removed - appId: application_1483412440498_0001 user: root queue: default #user-pending-applications: 0 #user-active-applications: 0 #queue-pending-applications: 0 #queue-active-applications: 0
2017-01-03 11:01:58,185 INFO org.apache.hadoop.yarn.server.resourcemanager.amlauncher.AMLauncher: Cleaning master appattempt_1483412440498_0001_000001
2017-01-03 11:01:58,186 INFO org.apache.hadoop.yarn.server.resourcemanager.scheduler.capacity.ParentQueue: Application removed - appId: application_1483412440498_0001 user: root leaf-queue of parent: root #applications: 0
2017-01-03 11:01:58,186 INFO org.apache.hadoop.yarn.server.resourcemanager.RMAuditLogger: USER=root	OPERATION=Application Finished - Succeeded	TARGET=RMAppManager	RESULT=SUCCESS	APPID=application_1483412440498_0001
2017-01-03 11:01:58,192 INFO org.apache.hadoop.yarn.server.resourcemanager.RMAppManager$ApplicationSummary: appId=application_1483412440498_0001,name=select count(1) from test(Stage-1),user=root,queue=default,state=FINISHED,trackingUrl=http://Master:8088/proxy/application_1483412440498_0001/,appMasterHost=tfs04,startTime=1483412484939,finishTime=1483412511639,finalStatus=SUCCEEDED,memorySeconds=94892,vcoreSeconds=58,preemptedAMContainers=0,preemptedNonAMContainers=0,preemptedResources=<memory:0\, vCores:0>,applicationType=MAPREDUCE
2017-01-03 11:02:00,182 INFO org.apache.hadoop.yarn.server.resourcemanager.scheduler.capacity.CapacityScheduler: Null container completed...
2017-01-03 11:10:40,426 INFO org.apache.hadoop.yarn.server.resourcemanager.scheduler.AbstractYarnScheduler: Release request cache is cleaned up
2017-01-03 11:36:47,046 INFO org.apache.hadoop.yarn.server.resourcemanager.ClientRMService: Allocated new applicationId: 2
2017-01-03 11:36:52,877 INFO org.apache.hadoop.yarn.server.resourcemanager.ClientRMService: Application with id 2 submitted by user root
2017-01-03 11:36:52,877 INFO org.apache.hadoop.yarn.server.resourcemanager.RMAuditLogger: USER=root	IP=192.168.50.11	OPERATION=Submit Application Request	TARGET=ClientRMService	RESULT=SUCCESS	APPID=application_1483412440498_0002
2017-01-03 11:36:52,877 INFO org.apache.hadoop.yarn.server.resourcemanager.rmapp.RMAppImpl: Storing application with id application_1483412440498_0002
2017-01-03 11:36:52,877 INFO org.apache.hadoop.yarn.server.resourcemanager.rmapp.RMAppImpl: application_1483412440498_0002 State change from NEW to NEW_SAVING
2017-01-03 11:36:52,878 INFO org.apache.hadoop.yarn.server.resourcemanager.recovery.RMStateStore: Storing info for app: application_1483412440498_0002
2017-01-03 11:36:52,878 INFO org.apache.hadoop.yarn.server.resourcemanager.rmapp.RMAppImpl: application_1483412440498_0002 State change from NEW_SAVING to SUBMITTED
2017-01-03 11:36:52,878 INFO org.apache.hadoop.yarn.server.resourcemanager.scheduler.capacity.ParentQueue: Application added - appId: application_1483412440498_0002 user: root leaf-queue of parent: root #applications: 1
2017-01-03 11:36:52,878 INFO org.apache.hadoop.yarn.server.resourcemanager.scheduler.capacity.CapacityScheduler: Accepted application application_1483412440498_0002 from user: root, in queue: default
2017-01-03 11:36:52,879 INFO org.apache.hadoop.yarn.server.resourcemanager.rmapp.RMAppImpl: application_1483412440498_0002 State change from SUBMITTED to ACCEPTED
2017-01-03 11:36:52,879 INFO org.apache.hadoop.yarn.server.resourcemanager.ApplicationMasterService: Registering app attempt : appattempt_1483412440498_0002_000001
2017-01-03 11:36:52,879 INFO org.apache.hadoop.yarn.server.resourcemanager.rmapp.attempt.RMAppAttemptImpl: appattempt_1483412440498_0002_000001 State change from NEW to SUBMITTED
2017-01-03 11:36:52,879 INFO org.apache.hadoop.yarn.server.resourcemanager.scheduler.capacity.LeafQueue: Application application_1483412440498_0002 from user: root activated in queue: default
2017-01-03 11:36:52,879 INFO org.apache.hadoop.yarn.server.resourcemanager.scheduler.capacity.LeafQueue: Application added - appId: application_1483412440498_0002 user: org.apache.hadoop.yarn.server.resourcemanager.scheduler.capacity.LeafQueue$User@7d108447, leaf-queue: default #user-pending-applications: 0 #user-active-applications: 1 #queue-pending-applications: 0 #queue-active-applications: 1
2017-01-03 11:36:52,879 INFO org.apache.hadoop.yarn.server.resourcemanager.scheduler.capacity.CapacityScheduler: Added Application Attempt appattempt_1483412440498_0002_000001 to scheduler from user root in queue default
2017-01-03 11:36:52,880 INFO org.apache.hadoop.yarn.server.resourcemanager.rmapp.attempt.RMAppAttemptImpl: appattempt_1483412440498_0002_000001 State change from SUBMITTED to SCHEDULED
2017-01-03 11:36:52,900 INFO org.apache.hadoop.yarn.server.resourcemanager.rmcontainer.RMContainerImpl: container_1483412440498_0002_01_000001 Container Transitioned from NEW to ALLOCATED
2017-01-03 11:36:52,900 INFO org.apache.hadoop.yarn.server.resourcemanager.RMAuditLogger: USER=root	OPERATION=AM Allocated Container	TARGET=SchedulerApp	RESULT=SUCCESS	APPID=application_1483412440498_0002	CONTAINERID=container_1483412440498_0002_01_000001
2017-01-03 11:36:52,900 INFO org.apache.hadoop.yarn.server.resourcemanager.scheduler.SchedulerNode: Assigned container container_1483412440498_0002_01_000001 of capacity <memory:2048, vCores:1> on host tfs03:45427, which has 1 containers, <memory:2048, vCores:1> used and <memory:6144, vCores:7> available after allocation
2017-01-03 11:36:52,900 INFO org.apache.hadoop.yarn.server.resourcemanager.scheduler.capacity.LeafQueue: assignedContainer application attempt=appattempt_1483412440498_0002_000001 container=Container: [ContainerId: container_1483412440498_0002_01_000001, NodeId: tfs03:45427, NodeHttpAddress: tfs03:8042, Resource: <memory:2048, vCores:1>, Priority: 0, Token: null, ] queue=default: capacity=1.0, absoluteCapacity=1.0, usedResources=<memory:0, vCores:0>, usedCapacity=0.0, absoluteUsedCapacity=0.0, numApps=1, numContainers=0 clusterResource=<memory:16384, vCores:16> type=OFF_SWITCH
2017-01-03 11:36:52,900 INFO org.apache.hadoop.yarn.server.resourcemanager.scheduler.capacity.ParentQueue: Re-sorting assigned queue: root.default stats: default: capacity=1.0, absoluteCapacity=1.0, usedResources=<memory:2048, vCores:1>, usedCapacity=0.125, absoluteUsedCapacity=0.125, numApps=1, numContainers=1
2017-01-03 11:36:52,901 INFO org.apache.hadoop.yarn.server.resourcemanager.scheduler.capacity.ParentQueue: assignedContainer queue=root usedCapacity=0.125 absoluteUsedCapacity=0.125 used=<memory:2048, vCores:1> cluster=<memory:16384, vCores:16>
2017-01-03 11:36:52,902 INFO org.apache.hadoop.yarn.server.resourcemanager.security.NMTokenSecretManagerInRM: Sending NMToken for nodeId : tfs03:45427 for container : container_1483412440498_0002_01_000001
2017-01-03 11:36:52,904 INFO org.apache.hadoop.yarn.server.resourcemanager.rmcontainer.RMContainerImpl: container_1483412440498_0002_01_000001 Container Transitioned from ALLOCATED to ACQUIRED
2017-01-03 11:36:52,904 INFO org.apache.hadoop.yarn.server.resourcemanager.security.NMTokenSecretManagerInRM: Clear node set for appattempt_1483412440498_0002_000001
2017-01-03 11:36:52,905 INFO org.apache.hadoop.yarn.server.resourcemanager.rmapp.attempt.RMAppAttemptImpl: Storing attempt: AppId: application_1483412440498_0002 AttemptId: appattempt_1483412440498_0002_000001 MasterContainer: Container: [ContainerId: container_1483412440498_0002_01_000001, NodeId: tfs03:45427, NodeHttpAddress: tfs03:8042, Resource: <memory:2048, vCores:1>, Priority: 0, Token: Token { kind: ContainerToken, service: 192.168.50.13:45427 }, ]
2017-01-03 11:36:52,905 INFO org.apache.hadoop.yarn.server.resourcemanager.rmapp.attempt.RMAppAttemptImpl: appattempt_1483412440498_0002_000001 State change from SCHEDULED to ALLOCATED_SAVING
2017-01-03 11:36:52,905 INFO org.apache.hadoop.yarn.server.resourcemanager.rmapp.attempt.RMAppAttemptImpl: appattempt_1483412440498_0002_000001 State change from ALLOCATED_SAVING to ALLOCATED
2017-01-03 11:36:52,906 INFO org.apache.hadoop.yarn.server.resourcemanager.amlauncher.AMLauncher: Launching masterappattempt_1483412440498_0002_000001
2017-01-03 11:36:52,912 INFO org.apache.hadoop.yarn.server.resourcemanager.amlauncher.AMLauncher: Setting up container Container: [ContainerId: container_1483412440498_0002_01_000001, NodeId: tfs03:45427, NodeHttpAddress: tfs03:8042, Resource: <memory:2048, vCores:1>, Priority: 0, Token: Token { kind: ContainerToken, service: 192.168.50.13:45427 }, ] for AM appattempt_1483412440498_0002_000001
2017-01-03 11:36:52,912 INFO org.apache.hadoop.yarn.server.resourcemanager.amlauncher.AMLauncher: Command to launch container container_1483412440498_0002_01_000001 : $JAVA_HOME/bin/java -Djava.io.tmpdir=$PWD/tmp -Dlog4j.configuration=container-log4j.properties -Dyarn.app.container.log.dir=<LOG_DIR> -Dyarn.app.container.log.filesize=0 -Dhadoop.root.logger=INFO,CLA -Dhadoop.root.logfile=syslog  -Xmx1024m org.apache.hadoop.mapreduce.v2.app.MRAppMaster 1><LOG_DIR>/stdout 2><LOG_DIR>/stderr 
2017-01-03 11:36:52,912 INFO org.apache.hadoop.yarn.server.resourcemanager.security.AMRMTokenSecretManager: Create AMRMToken for ApplicationAttempt: appattempt_1483412440498_0002_000001
2017-01-03 11:36:52,912 INFO org.apache.hadoop.yarn.server.resourcemanager.security.AMRMTokenSecretManager: Creating password for appattempt_1483412440498_0002_000001
2017-01-03 11:36:52,941 INFO org.apache.hadoop.yarn.server.resourcemanager.amlauncher.AMLauncher: Done launching container Container: [ContainerId: container_1483412440498_0002_01_000001, NodeId: tfs03:45427, NodeHttpAddress: tfs03:8042, Resource: <memory:2048, vCores:1>, Priority: 0, Token: Token { kind: ContainerToken, service: 192.168.50.13:45427 }, ] for AM appattempt_1483412440498_0002_000001
2017-01-03 11:36:52,941 INFO org.apache.hadoop.yarn.server.resourcemanager.rmapp.attempt.RMAppAttemptImpl: appattempt_1483412440498_0002_000001 State change from ALLOCATED to LAUNCHED
2017-01-03 11:36:53,901 INFO org.apache.hadoop.yarn.server.resourcemanager.rmcontainer.RMContainerImpl: container_1483412440498_0002_01_000001 Container Transitioned from ACQUIRED to RUNNING
2017-01-03 11:37:00,636 INFO SecurityLogger.org.apache.hadoop.ipc.Server: Auth successful for appattempt_1483412440498_0002_000001 (auth:SIMPLE)
2017-01-03 11:37:00,641 INFO org.apache.hadoop.yarn.server.resourcemanager.ApplicationMasterService: AM registration appattempt_1483412440498_0002_000001
2017-01-03 11:37:00,641 INFO org.apache.hadoop.yarn.server.resourcemanager.RMAuditLogger: USER=root	IP=192.168.50.13	OPERATION=Register App Master	TARGET=ApplicationMasterService	RESULT=SUCCESS	APPID=application_1483412440498_0002	APPATTEMPTID=appattempt_1483412440498_0002_000001
2017-01-03 11:37:00,641 INFO org.apache.hadoop.yarn.server.resourcemanager.rmapp.attempt.RMAppAttemptImpl: appattempt_1483412440498_0002_000001 State change from LAUNCHED to RUNNING
2017-01-03 11:37:00,641 INFO org.apache.hadoop.yarn.server.resourcemanager.rmapp.RMAppImpl: application_1483412440498_0002 State change from ACCEPTED to RUNNING
2017-01-03 11:37:01,911 INFO org.apache.hadoop.yarn.server.resourcemanager.rmcontainer.RMContainerImpl: container_1483412440498_0002_01_000002 Container Transitioned from NEW to ALLOCATED
2017-01-03 11:37:01,911 INFO org.apache.hadoop.yarn.server.resourcemanager.RMAuditLogger: USER=root	OPERATION=AM Allocated Container	TARGET=SchedulerApp	RESULT=SUCCESS	APPID=application_1483412440498_0002	CONTAINERID=container_1483412440498_0002_01_000002
2017-01-03 11:37:01,915 INFO org.apache.hadoop.yarn.server.resourcemanager.scheduler.SchedulerNode: Assigned container container_1483412440498_0002_01_000002 of capacity <memory:1024, vCores:1> on host tfs03:45427, which has 2 containers, <memory:3072, vCores:2> used and <memory:5120, vCores:6> available after allocation
2017-01-03 11:37:01,915 INFO org.apache.hadoop.yarn.server.resourcemanager.scheduler.capacity.LeafQueue: assignedContainer application attempt=appattempt_1483412440498_0002_000001 container=Container: [ContainerId: container_1483412440498_0002_01_000002, NodeId: tfs03:45427, NodeHttpAddress: tfs03:8042, Resource: <memory:1024, vCores:1>, Priority: 20, Token: null, ] queue=default: capacity=1.0, absoluteCapacity=1.0, usedResources=<memory:2048, vCores:1>, usedCapacity=0.125, absoluteUsedCapacity=0.125, numApps=1, numContainers=1 clusterResource=<memory:16384, vCores:16> type=NODE_LOCAL
2017-01-03 11:37:01,915 INFO org.apache.hadoop.yarn.server.resourcemanager.scheduler.capacity.ParentQueue: Re-sorting assigned queue: root.default stats: default: capacity=1.0, absoluteCapacity=1.0, usedResources=<memory:3072, vCores:2>, usedCapacity=0.1875, absoluteUsedCapacity=0.1875, numApps=1, numContainers=2
2017-01-03 11:37:01,915 INFO org.apache.hadoop.yarn.server.resourcemanager.scheduler.capacity.ParentQueue: assignedContainer queue=root usedCapacity=0.1875 absoluteUsedCapacity=0.1875 used=<memory:3072, vCores:2> cluster=<memory:16384, vCores:16>
2017-01-03 11:37:02,532 INFO org.apache.hadoop.yarn.server.resourcemanager.rmcontainer.RMContainerImpl: container_1483412440498_0002_01_000003 Container Transitioned from NEW to ALLOCATED
2017-01-03 11:37:02,532 INFO org.apache.hadoop.yarn.server.resourcemanager.RMAuditLogger: USER=root	OPERATION=AM Allocated Container	TARGET=SchedulerApp	RESULT=SUCCESS	APPID=application_1483412440498_0002	CONTAINERID=container_1483412440498_0002_01_000003
2017-01-03 11:37:02,532 INFO org.apache.hadoop.yarn.server.resourcemanager.scheduler.SchedulerNode: Assigned container container_1483412440498_0002_01_000003 of capacity <memory:1024, vCores:1> on host tfs04:38559, which has 1 containers, <memory:1024, vCores:1> used and <memory:7168, vCores:7> available after allocation
2017-01-03 11:37:02,533 INFO org.apache.hadoop.yarn.server.resourcemanager.scheduler.capacity.LeafQueue: assignedContainer application attempt=appattempt_1483412440498_0002_000001 container=Container: [ContainerId: container_1483412440498_0002_01_000003, NodeId: tfs04:38559, NodeHttpAddress: tfs04:8042, Resource: <memory:1024, vCores:1>, Priority: 20, Token: null, ] queue=default: capacity=1.0, absoluteCapacity=1.0, usedResources=<memory:3072, vCores:2>, usedCapacity=0.1875, absoluteUsedCapacity=0.1875, numApps=1, numContainers=2 clusterResource=<memory:16384, vCores:16> type=OFF_SWITCH
2017-01-03 11:37:02,533 INFO org.apache.hadoop.yarn.server.resourcemanager.scheduler.capacity.ParentQueue: Re-sorting assigned queue: root.default stats: default: capacity=1.0, absoluteCapacity=1.0, usedResources=<memory:4096, vCores:3>, usedCapacity=0.25, absoluteUsedCapacity=0.25, numApps=1, numContainers=3
2017-01-03 11:37:02,533 INFO org.apache.hadoop.yarn.server.resourcemanager.scheduler.capacity.ParentQueue: assignedContainer queue=root usedCapacity=0.25 absoluteUsedCapacity=0.25 used=<memory:4096, vCores:3> cluster=<memory:16384, vCores:16>
2017-01-03 11:37:02,713 INFO org.apache.hadoop.yarn.server.resourcemanager.security.NMTokenSecretManagerInRM: Sending NMToken for nodeId : tfs03:45427 for container : container_1483412440498_0002_01_000002
2017-01-03 11:37:02,719 INFO org.apache.hadoop.yarn.server.resourcemanager.rmcontainer.RMContainerImpl: container_1483412440498_0002_01_000002 Container Transitioned from ALLOCATED to ACQUIRED
2017-01-03 11:37:02,732 INFO org.apache.hadoop.yarn.server.resourcemanager.security.NMTokenSecretManagerInRM: Sending NMToken for nodeId : tfs04:38559 for container : container_1483412440498_0002_01_000003
2017-01-03 11:37:02,734 INFO org.apache.hadoop.yarn.server.resourcemanager.rmcontainer.RMContainerImpl: container_1483412440498_0002_01_000003 Container Transitioned from ALLOCATED to ACQUIRED
2017-01-03 11:37:03,748 INFO org.apache.hadoop.yarn.server.resourcemanager.scheduler.AppSchedulingInfo: checking for deactivate of application :application_1483412440498_0002
2017-01-03 11:37:03,913 INFO org.apache.hadoop.yarn.server.resourcemanager.rmcontainer.RMContainerImpl: container_1483412440498_0002_01_000002 Container Transitioned from ACQUIRED to RUNNING
2017-01-03 11:37:04,535 INFO org.apache.hadoop.yarn.server.resourcemanager.rmcontainer.RMContainerImpl: container_1483412440498_0002_01_000003 Container Transitioned from ACQUIRED to RUNNING
2017-01-03 11:37:10,631 INFO org.apache.hadoop.yarn.server.resourcemanager.rmcontainer.RMContainerImpl: container_1483412440498_0002_01_000002 Container Transitioned from RUNNING to COMPLETED
2017-01-03 11:37:10,631 INFO org.apache.hadoop.yarn.server.resourcemanager.scheduler.common.fica.FiCaSchedulerApp: Completed container: container_1483412440498_0002_01_000002 in state: COMPLETED event:FINISHED
2017-01-03 11:37:10,631 INFO org.apache.hadoop.yarn.server.resourcemanager.RMAuditLogger: USER=root	OPERATION=AM Released Container	TARGET=SchedulerApp	RESULT=SUCCESS	APPID=application_1483412440498_0002	CONTAINERID=container_1483412440498_0002_01_000002
2017-01-03 11:37:10,631 INFO org.apache.hadoop.yarn.server.resourcemanager.scheduler.SchedulerNode: Released container container_1483412440498_0002_01_000002 of capacity <memory:1024, vCores:1> on host tfs03:45427, which currently has 1 containers, <memory:2048, vCores:1> used and <memory:6144, vCores:7> available, release resources=true
2017-01-03 11:37:10,631 INFO org.apache.hadoop.yarn.server.resourcemanager.scheduler.capacity.LeafQueue: default used=<memory:3072, vCores:2> numContainers=2 user=root user-resources=<memory:3072, vCores:2>
2017-01-03 11:37:10,632 INFO org.apache.hadoop.yarn.server.resourcemanager.scheduler.capacity.LeafQueue: completedContainer container=Container: [ContainerId: container_1483412440498_0002_01_000002, NodeId: tfs03:45427, NodeHttpAddress: tfs03:8042, Resource: <memory:1024, vCores:1>, Priority: 20, Token: Token { kind: ContainerToken, service: 192.168.50.13:45427 }, ] queue=default: capacity=1.0, absoluteCapacity=1.0, usedResources=<memory:3072, vCores:2>, usedCapacity=0.1875, absoluteUsedCapacity=0.1875, numApps=1, numContainers=2 cluster=<memory:16384, vCores:16>
2017-01-03 11:37:10,632 INFO org.apache.hadoop.yarn.server.resourcemanager.scheduler.capacity.ParentQueue: completedContainer queue=root usedCapacity=0.1875 absoluteUsedCapacity=0.1875 used=<memory:3072, vCores:2> cluster=<memory:16384, vCores:16>
2017-01-03 11:37:10,632 INFO org.apache.hadoop.yarn.server.resourcemanager.scheduler.capacity.ParentQueue: Re-sorting completed queue: root.default stats: default: capacity=1.0, absoluteCapacity=1.0, usedResources=<memory:3072, vCores:2>, usedCapacity=0.1875, absoluteUsedCapacity=0.1875, numApps=1, numContainers=2
2017-01-03 11:37:10,633 INFO org.apache.hadoop.yarn.server.resourcemanager.scheduler.capacity.CapacityScheduler: Application attempt appattempt_1483412440498_0002_000001 released container container_1483412440498_0002_01_000002 on node: host: tfs03:45427 #containers=1 available=<memory:6144, vCores:7> used=<memory:2048, vCores:1> with event: FINISHED
2017-01-03 11:37:12,543 INFO org.apache.hadoop.yarn.server.resourcemanager.rmcontainer.RMContainerImpl: container_1483412440498_0002_01_000004 Container Transitioned from NEW to ALLOCATED
2017-01-03 11:37:12,543 INFO org.apache.hadoop.yarn.server.resourcemanager.RMAuditLogger: USER=root	OPERATION=AM Allocated Container	TARGET=SchedulerApp	RESULT=SUCCESS	APPID=application_1483412440498_0002	CONTAINERID=container_1483412440498_0002_01_000004
2017-01-03 11:37:12,543 INFO org.apache.hadoop.yarn.server.resourcemanager.scheduler.SchedulerNode: Assigned container container_1483412440498_0002_01_000004 of capacity <memory:1024, vCores:1> on host tfs04:38559, which has 2 containers, <memory:2048, vCores:2> used and <memory:6144, vCores:6> available after allocation
2017-01-03 11:37:12,544 INFO org.apache.hadoop.yarn.server.resourcemanager.scheduler.capacity.LeafQueue: assignedContainer application attempt=appattempt_1483412440498_0002_000001 container=Container: [ContainerId: container_1483412440498_0002_01_000004, NodeId: tfs04:38559, NodeHttpAddress: tfs04:8042, Resource: <memory:1024, vCores:1>, Priority: 10, Token: null, ] queue=default: capacity=1.0, absoluteCapacity=1.0, usedResources=<memory:3072, vCores:2>, usedCapacity=0.1875, absoluteUsedCapacity=0.1875, numApps=1, numContainers=2 clusterResource=<memory:16384, vCores:16> type=OFF_SWITCH
2017-01-03 11:37:12,544 INFO org.apache.hadoop.yarn.server.resourcemanager.scheduler.capacity.ParentQueue: Re-sorting assigned queue: root.default stats: default: capacity=1.0, absoluteCapacity=1.0, usedResources=<memory:4096, vCores:3>, usedCapacity=0.25, absoluteUsedCapacity=0.25, numApps=1, numContainers=3
2017-01-03 11:37:12,544 INFO org.apache.hadoop.yarn.server.resourcemanager.scheduler.capacity.ParentQueue: assignedContainer queue=root usedCapacity=0.25 absoluteUsedCapacity=0.25 used=<memory:4096, vCores:3> cluster=<memory:16384, vCores:16>
2017-01-03 11:37:12,783 INFO org.apache.hadoop.yarn.server.resourcemanager.rmcontainer.RMContainerImpl: container_1483412440498_0002_01_000004 Container Transitioned from ALLOCATED to ACQUIRED
2017-01-03 11:37:13,544 INFO org.apache.hadoop.yarn.server.resourcemanager.rmcontainer.RMContainerImpl: container_1483412440498_0002_01_000004 Container Transitioned from ACQUIRED to RUNNING
2017-01-03 11:37:13,790 INFO org.apache.hadoop.yarn.server.resourcemanager.scheduler.AppSchedulingInfo: checking for deactivate of application :application_1483412440498_0002
2017-01-03 11:37:15,607 INFO org.apache.hadoop.yarn.server.resourcemanager.rmcontainer.RMContainerImpl: container_1483412440498_0002_01_000003 Container Transitioned from RUNNING to COMPLETED
2017-01-03 11:37:15,607 INFO org.apache.hadoop.yarn.server.resourcemanager.scheduler.common.fica.FiCaSchedulerApp: Completed container: container_1483412440498_0002_01_000003 in state: COMPLETED event:FINISHED
2017-01-03 11:37:15,607 INFO org.apache.hadoop.yarn.server.resourcemanager.RMAuditLogger: USER=root	OPERATION=AM Released Container	TARGET=SchedulerApp	RESULT=SUCCESS	APPID=application_1483412440498_0002	CONTAINERID=container_1483412440498_0002_01_000003
2017-01-03 11:37:15,607 INFO org.apache.hadoop.yarn.server.resourcemanager.scheduler.SchedulerNode: Released container container_1483412440498_0002_01_000003 of capacity <memory:1024, vCores:1> on host tfs04:38559, which currently has 1 containers, <memory:1024, vCores:1> used and <memory:7168, vCores:7> available, release resources=true
2017-01-03 11:37:15,607 INFO org.apache.hadoop.yarn.server.resourcemanager.scheduler.capacity.LeafQueue: default used=<memory:3072, vCores:2> numContainers=2 user=root user-resources=<memory:3072, vCores:2>
2017-01-03 11:37:15,607 INFO org.apache.hadoop.yarn.server.resourcemanager.scheduler.capacity.LeafQueue: completedContainer container=Container: [ContainerId: container_1483412440498_0002_01_000003, NodeId: tfs04:38559, NodeHttpAddress: tfs04:8042, Resource: <memory:1024, vCores:1>, Priority: 20, Token: Token { kind: ContainerToken, service: 192.168.50.14:38559 }, ] queue=default: capacity=1.0, absoluteCapacity=1.0, usedResources=<memory:3072, vCores:2>, usedCapacity=0.1875, absoluteUsedCapacity=0.1875, numApps=1, numContainers=2 cluster=<memory:16384, vCores:16>
2017-01-03 11:37:15,607 INFO org.apache.hadoop.yarn.server.resourcemanager.scheduler.capacity.ParentQueue: completedContainer queue=root usedCapacity=0.1875 absoluteUsedCapacity=0.1875 used=<memory:3072, vCores:2> cluster=<memory:16384, vCores:16>
2017-01-03 11:37:15,608 INFO org.apache.hadoop.yarn.server.resourcemanager.scheduler.capacity.ParentQueue: Re-sorting completed queue: root.default stats: default: capacity=1.0, absoluteCapacity=1.0, usedResources=<memory:3072, vCores:2>, usedCapacity=0.1875, absoluteUsedCapacity=0.1875, numApps=1, numContainers=2
2017-01-03 11:37:15,608 INFO org.apache.hadoop.yarn.server.resourcemanager.scheduler.capacity.CapacityScheduler: Application attempt appattempt_1483412440498_0002_000001 released container container_1483412440498_0002_01_000003 on node: host: tfs04:38559 #containers=1 available=<memory:7168, vCores:7> used=<memory:1024, vCores:1> with event: FINISHED
2017-01-03 11:37:17,472 INFO org.apache.hadoop.yarn.server.resourcemanager.rmcontainer.RMContainerImpl: container_1483412440498_0002_01_000004 Container Transitioned from RUNNING to COMPLETED
2017-01-03 11:37:17,472 INFO org.apache.hadoop.yarn.server.resourcemanager.scheduler.common.fica.FiCaSchedulerApp: Completed container: container_1483412440498_0002_01_000004 in state: COMPLETED event:FINISHED
2017-01-03 11:37:17,472 INFO org.apache.hadoop.yarn.server.resourcemanager.RMAuditLogger: USER=root	OPERATION=AM Released Container	TARGET=SchedulerApp	RESULT=SUCCESS	APPID=application_1483412440498_0002	CONTAINERID=container_1483412440498_0002_01_000004
2017-01-03 11:37:17,472 INFO org.apache.hadoop.yarn.server.resourcemanager.scheduler.SchedulerNode: Released container container_1483412440498_0002_01_000004 of capacity <memory:1024, vCores:1> on host tfs04:38559, which currently has 0 containers, <memory:0, vCores:0> used and <memory:8192, vCores:8> available, release resources=true
2017-01-03 11:37:17,472 INFO org.apache.hadoop.yarn.server.resourcemanager.scheduler.capacity.LeafQueue: default used=<memory:2048, vCores:1> numContainers=1 user=root user-resources=<memory:2048, vCores:1>
2017-01-03 11:37:17,473 INFO org.apache.hadoop.yarn.server.resourcemanager.scheduler.capacity.LeafQueue: completedContainer container=Container: [ContainerId: container_1483412440498_0002_01_000004, NodeId: tfs04:38559, NodeHttpAddress: tfs04:8042, Resource: <memory:1024, vCores:1>, Priority: 10, Token: Token { kind: ContainerToken, service: 192.168.50.14:38559 }, ] queue=default: capacity=1.0, absoluteCapacity=1.0, usedResources=<memory:2048, vCores:1>, usedCapacity=0.125, absoluteUsedCapacity=0.125, numApps=1, numContainers=1 cluster=<memory:16384, vCores:16>
2017-01-03 11:37:17,473 INFO org.apache.hadoop.yarn.server.resourcemanager.scheduler.capacity.ParentQueue: completedContainer queue=root usedCapacity=0.125 absoluteUsedCapacity=0.125 used=<memory:2048, vCores:1> cluster=<memory:16384, vCores:16>
2017-01-03 11:37:17,473 INFO org.apache.hadoop.yarn.server.resourcemanager.scheduler.capacity.ParentQueue: Re-sorting completed queue: root.default stats: default: capacity=1.0, absoluteCapacity=1.0, usedResources=<memory:2048, vCores:1>, usedCapacity=0.125, absoluteUsedCapacity=0.125, numApps=1, numContainers=1
2017-01-03 11:37:17,473 INFO org.apache.hadoop.yarn.server.resourcemanager.scheduler.capacity.CapacityScheduler: Application attempt appattempt_1483412440498_0002_000001 released container container_1483412440498_0002_01_000004 on node: host: tfs04:38559 #containers=0 available=<memory:8192, vCores:8> used=<memory:0, vCores:0> with event: FINISHED
2017-01-03 11:37:17,607 INFO org.apache.hadoop.yarn.server.resourcemanager.rmapp.attempt.RMAppAttemptImpl: Updating application attempt appattempt_1483412440498_0002_000001 with final state: FINISHING, and exit status: -1000
2017-01-03 11:37:17,607 INFO org.apache.hadoop.yarn.server.resourcemanager.rmapp.attempt.RMAppAttemptImpl: appattempt_1483412440498_0002_000001 State change from RUNNING to FINAL_SAVING
2017-01-03 11:37:17,607 INFO org.apache.hadoop.yarn.server.resourcemanager.rmapp.RMAppImpl: Updating application application_1483412440498_0002 with final state: FINISHING
2017-01-03 11:37:17,607 INFO org.apache.hadoop.yarn.server.resourcemanager.rmapp.RMAppImpl: application_1483412440498_0002 State change from RUNNING to FINAL_SAVING
2017-01-03 11:37:17,608 INFO org.apache.hadoop.yarn.server.resourcemanager.recovery.RMStateStore: Updating info for app: application_1483412440498_0002
2017-01-03 11:37:17,608 INFO org.apache.hadoop.yarn.server.resourcemanager.rmapp.attempt.RMAppAttemptImpl: appattempt_1483412440498_0002_000001 State change from FINAL_SAVING to FINISHING
2017-01-03 11:37:17,608 INFO org.apache.hadoop.yarn.server.resourcemanager.rmapp.RMAppImpl: application_1483412440498_0002 State change from FINAL_SAVING to FINISHING
2017-01-03 11:37:18,611 INFO org.apache.hadoop.yarn.server.resourcemanager.ApplicationMasterService: application_1483412440498_0002 unregistered successfully. 
2017-01-03 11:37:24,108 INFO org.apache.hadoop.yarn.server.resourcemanager.rmcontainer.RMContainerImpl: container_1483412440498_0002_01_000001 Container Transitioned from RUNNING to COMPLETED
2017-01-03 11:37:24,108 INFO org.apache.hadoop.yarn.server.resourcemanager.ApplicationMasterService: Unregistering app attempt : appattempt_1483412440498_0002_000001
2017-01-03 11:37:24,109 INFO org.apache.hadoop.yarn.server.resourcemanager.scheduler.common.fica.FiCaSchedulerApp: Completed container: container_1483412440498_0002_01_000001 in state: COMPLETED event:FINISHED
2017-01-03 11:37:24,109 INFO org.apache.hadoop.yarn.server.resourcemanager.security.AMRMTokenSecretManager: Application finished, removing password for appattempt_1483412440498_0002_000001
2017-01-03 11:37:24,109 INFO org.apache.hadoop.yarn.server.resourcemanager.RMAuditLogger: USER=root	OPERATION=AM Released Container	TARGET=SchedulerApp	RESULT=SUCCESS	APPID=application_1483412440498_0002	CONTAINERID=container_1483412440498_0002_01_000001
2017-01-03 11:37:24,109 INFO org.apache.hadoop.yarn.server.resourcemanager.rmapp.attempt.RMAppAttemptImpl: appattempt_1483412440498_0002_000001 State change from FINISHING to FINISHED
2017-01-03 11:37:24,109 INFO org.apache.hadoop.yarn.server.resourcemanager.scheduler.SchedulerNode: Released container container_1483412440498_0002_01_000001 of capacity <memory:2048, vCores:1> on host tfs03:45427, which currently has 0 containers, <memory:0, vCores:0> used and <memory:8192, vCores:8> available, release resources=true
2017-01-03 11:37:24,110 INFO org.apache.hadoop.yarn.server.resourcemanager.rmapp.RMAppImpl: application_1483412440498_0002 State change from FINISHING to FINISHED
2017-01-03 11:37:24,110 INFO org.apache.hadoop.yarn.server.resourcemanager.scheduler.capacity.LeafQueue: default used=<memory:0, vCores:0> numContainers=0 user=root user-resources=<memory:0, vCores:0>
2017-01-03 11:37:24,110 INFO org.apache.hadoop.yarn.server.resourcemanager.RMAuditLogger: USER=root	OPERATION=Application Finished - Succeeded	TARGET=RMAppManager	RESULT=SUCCESS	APPID=application_1483412440498_0002
2017-01-03 11:37:24,110 INFO org.apache.hadoop.yarn.server.resourcemanager.scheduler.capacity.LeafQueue: completedContainer container=Container: [ContainerId: container_1483412440498_0002_01_000001, NodeId: tfs03:45427, NodeHttpAddress: tfs03:8042, Resource: <memory:2048, vCores:1>, Priority: 0, Token: Token { kind: ContainerToken, service: 192.168.50.13:45427 }, ] queue=default: capacity=1.0, absoluteCapacity=1.0, usedResources=<memory:0, vCores:0>, usedCapacity=0.0, absoluteUsedCapacity=0.0, numApps=1, numContainers=0 cluster=<memory:16384, vCores:16>
2017-01-03 11:37:24,110 INFO org.apache.hadoop.yarn.server.resourcemanager.scheduler.capacity.ParentQueue: completedContainer queue=root usedCapacity=0.0 absoluteUsedCapacity=0.0 used=<memory:0, vCores:0> cluster=<memory:16384, vCores:16>
2017-01-03 11:37:24,110 INFO org.apache.hadoop.yarn.server.resourcemanager.scheduler.capacity.ParentQueue: Re-sorting completed queue: root.default stats: default: capacity=1.0, absoluteCapacity=1.0, usedResources=<memory:0, vCores:0>, usedCapacity=0.0, absoluteUsedCapacity=0.0, numApps=1, numContainers=0
2017-01-03 11:37:24,110 INFO org.apache.hadoop.yarn.server.resourcemanager.scheduler.capacity.CapacityScheduler: Application attempt appattempt_1483412440498_0002_000001 released container container_1483412440498_0002_01_000001 on node: host: tfs03:45427 #containers=0 available=<memory:8192, vCores:8> used=<memory:0, vCores:0> with event: FINISHED
2017-01-03 11:37:24,111 INFO org.apache.hadoop.yarn.server.resourcemanager.scheduler.capacity.CapacityScheduler: Application Attempt appattempt_1483412440498_0002_000001 is done. finalState=FINISHED
2017-01-03 11:37:24,111 INFO org.apache.hadoop.yarn.server.resourcemanager.RMAppManager$ApplicationSummary: appId=application_1483412440498_0002,name=select count(*) from name_city(Stage-1),user=root,queue=default,state=FINISHED,trackingUrl=http://Master:8088/proxy/application_1483412440498_0002/,appMasterHost=tfs03,startTime=1483414612877,finishTime=1483414637607,finalStatus=SUCCEEDED,memorySeconds=91277,vcoreSeconds=56,preemptedAMContainers=0,preemptedNonAMContainers=0,preemptedResources=<memory:0\, vCores:0>,applicationType=MAPREDUCE
2017-01-03 11:37:24,111 INFO org.apache.hadoop.yarn.server.resourcemanager.scheduler.AppSchedulingInfo: Application application_1483412440498_0002 requests cleared
2017-01-03 11:37:24,128 INFO org.apache.hadoop.yarn.server.resourcemanager.scheduler.capacity.LeafQueue: Application removed - appId: application_1483412440498_0002 user: root queue: default #user-pending-applications: 0 #user-active-applications: 0 #queue-pending-applications: 0 #queue-active-applications: 0
2017-01-03 11:37:24,128 INFO org.apache.hadoop.yarn.server.resourcemanager.scheduler.capacity.ParentQueue: Application removed - appId: application_1483412440498_0002 user: root leaf-queue of parent: root #applications: 0
2017-01-03 11:37:24,131 INFO org.apache.hadoop.yarn.server.resourcemanager.amlauncher.AMLauncher: Cleaning master appattempt_1483412440498_0002_000001
2017-01-03 11:37:25,482 INFO org.apache.hadoop.yarn.server.resourcemanager.scheduler.capacity.CapacityScheduler: Null container completed...
2017-01-03 11:39:26,147 INFO org.apache.hadoop.yarn.server.resourcemanager.ClientRMService: Allocated new applicationId: 3
2017-01-03 11:39:31,827 INFO org.apache.hadoop.yarn.server.resourcemanager.ClientRMService: Application with id 3 submitted by user root
2017-01-03 11:39:31,827 INFO org.apache.hadoop.yarn.server.resourcemanager.RMAuditLogger: USER=root	IP=192.168.50.11	OPERATION=Submit Application Request	TARGET=ClientRMService	RESULT=SUCCESS	APPID=application_1483412440498_0003
2017-01-03 11:39:31,827 INFO org.apache.hadoop.yarn.server.resourcemanager.rmapp.RMAppImpl: Storing application with id application_1483412440498_0003
2017-01-03 11:39:31,827 INFO org.apache.hadoop.yarn.server.resourcemanager.rmapp.RMAppImpl: application_1483412440498_0003 State change from NEW to NEW_SAVING
2017-01-03 11:39:31,827 INFO org.apache.hadoop.yarn.server.resourcemanager.recovery.RMStateStore: Storing info for app: application_1483412440498_0003
2017-01-03 11:39:31,828 INFO org.apache.hadoop.yarn.server.resourcemanager.rmapp.RMAppImpl: application_1483412440498_0003 State change from NEW_SAVING to SUBMITTED
2017-01-03 11:39:31,828 INFO org.apache.hadoop.yarn.server.resourcemanager.scheduler.capacity.ParentQueue: Application added - appId: application_1483412440498_0003 user: root leaf-queue of parent: root #applications: 1
2017-01-03 11:39:31,828 INFO org.apache.hadoop.yarn.server.resourcemanager.scheduler.capacity.CapacityScheduler: Accepted application application_1483412440498_0003 from user: root, in queue: default
2017-01-03 11:39:31,829 INFO org.apache.hadoop.yarn.server.resourcemanager.rmapp.RMAppImpl: application_1483412440498_0003 State change from SUBMITTED to ACCEPTED
2017-01-03 11:39:31,829 INFO org.apache.hadoop.yarn.server.resourcemanager.ApplicationMasterService: Registering app attempt : appattempt_1483412440498_0003_000001
2017-01-03 11:39:31,829 INFO org.apache.hadoop.yarn.server.resourcemanager.rmapp.attempt.RMAppAttemptImpl: appattempt_1483412440498_0003_000001 State change from NEW to SUBMITTED
2017-01-03 11:39:31,829 INFO org.apache.hadoop.yarn.server.resourcemanager.scheduler.capacity.LeafQueue: Application application_1483412440498_0003 from user: root activated in queue: default
2017-01-03 11:39:31,829 INFO org.apache.hadoop.yarn.server.resourcemanager.scheduler.capacity.LeafQueue: Application added - appId: application_1483412440498_0003 user: org.apache.hadoop.yarn.server.resourcemanager.scheduler.capacity.LeafQueue$User@5601c987, leaf-queue: default #user-pending-applications: 0 #user-active-applications: 1 #queue-pending-applications: 0 #queue-active-applications: 1
2017-01-03 11:39:31,829 INFO org.apache.hadoop.yarn.server.resourcemanager.scheduler.capacity.CapacityScheduler: Added Application Attempt appattempt_1483412440498_0003_000001 to scheduler from user root in queue default
2017-01-03 11:39:31,830 INFO org.apache.hadoop.yarn.server.resourcemanager.rmapp.attempt.RMAppAttemptImpl: appattempt_1483412440498_0003_000001 State change from SUBMITTED to SCHEDULED
2017-01-03 11:39:32,243 INFO org.apache.hadoop.yarn.server.resourcemanager.rmcontainer.RMContainerImpl: container_1483412440498_0003_01_000001 Container Transitioned from NEW to ALLOCATED
2017-01-03 11:39:32,244 INFO org.apache.hadoop.yarn.server.resourcemanager.RMAuditLogger: USER=root	OPERATION=AM Allocated Container	TARGET=SchedulerApp	RESULT=SUCCESS	APPID=application_1483412440498_0003	CONTAINERID=container_1483412440498_0003_01_000001
2017-01-03 11:39:32,244 INFO org.apache.hadoop.yarn.server.resourcemanager.scheduler.SchedulerNode: Assigned container container_1483412440498_0003_01_000001 of capacity <memory:2048, vCores:1> on host tfs03:45427, which has 1 containers, <memory:2048, vCores:1> used and <memory:6144, vCores:7> available after allocation
2017-01-03 11:39:32,244 INFO org.apache.hadoop.yarn.server.resourcemanager.scheduler.capacity.LeafQueue: assignedContainer application attempt=appattempt_1483412440498_0003_000001 container=Container: [ContainerId: container_1483412440498_0003_01_000001, NodeId: tfs03:45427, NodeHttpAddress: tfs03:8042, Resource: <memory:2048, vCores:1>, Priority: 0, Token: null, ] queue=default: capacity=1.0, absoluteCapacity=1.0, usedResources=<memory:0, vCores:0>, usedCapacity=0.0, absoluteUsedCapacity=0.0, numApps=1, numContainers=0 clusterResource=<memory:16384, vCores:16> type=OFF_SWITCH
2017-01-03 11:39:32,244 INFO org.apache.hadoop.yarn.server.resourcemanager.scheduler.capacity.ParentQueue: Re-sorting assigned queue: root.default stats: default: capacity=1.0, absoluteCapacity=1.0, usedResources=<memory:2048, vCores:1>, usedCapacity=0.125, absoluteUsedCapacity=0.125, numApps=1, numContainers=1
2017-01-03 11:39:32,244 INFO org.apache.hadoop.yarn.server.resourcemanager.scheduler.capacity.ParentQueue: assignedContainer queue=root usedCapacity=0.125 absoluteUsedCapacity=0.125 used=<memory:2048, vCores:1> cluster=<memory:16384, vCores:16>
2017-01-03 11:39:32,245 INFO org.apache.hadoop.yarn.server.resourcemanager.security.NMTokenSecretManagerInRM: Sending NMToken for nodeId : tfs03:45427 for container : container_1483412440498_0003_01_000001
2017-01-03 11:39:32,247 INFO org.apache.hadoop.yarn.server.resourcemanager.rmcontainer.RMContainerImpl: container_1483412440498_0003_01_000001 Container Transitioned from ALLOCATED to ACQUIRED
2017-01-03 11:39:32,466 INFO org.apache.hadoop.yarn.server.resourcemanager.security.NMTokenSecretManagerInRM: Clear node set for appattempt_1483412440498_0003_000001
2017-01-03 11:39:32,467 INFO org.apache.hadoop.yarn.server.resourcemanager.rmapp.attempt.RMAppAttemptImpl: Storing attempt: AppId: application_1483412440498_0003 AttemptId: appattempt_1483412440498_0003_000001 MasterContainer: Container: [ContainerId: container_1483412440498_0003_01_000001, NodeId: tfs03:45427, NodeHttpAddress: tfs03:8042, Resource: <memory:2048, vCores:1>, Priority: 0, Token: Token { kind: ContainerToken, service: 192.168.50.13:45427 }, ]
2017-01-03 11:39:32,467 INFO org.apache.hadoop.yarn.server.resourcemanager.rmapp.attempt.RMAppAttemptImpl: appattempt_1483412440498_0003_000001 State change from SCHEDULED to ALLOCATED_SAVING
2017-01-03 11:39:32,467 INFO org.apache.hadoop.yarn.server.resourcemanager.rmapp.attempt.RMAppAttemptImpl: appattempt_1483412440498_0003_000001 State change from ALLOCATED_SAVING to ALLOCATED
2017-01-03 11:39:32,468 INFO org.apache.hadoop.yarn.server.resourcemanager.amlauncher.AMLauncher: Launching masterappattempt_1483412440498_0003_000001
2017-01-03 11:39:32,469 INFO org.apache.hadoop.yarn.server.resourcemanager.amlauncher.AMLauncher: Setting up container Container: [ContainerId: container_1483412440498_0003_01_000001, NodeId: tfs03:45427, NodeHttpAddress: tfs03:8042, Resource: <memory:2048, vCores:1>, Priority: 0, Token: Token { kind: ContainerToken, service: 192.168.50.13:45427 }, ] for AM appattempt_1483412440498_0003_000001
2017-01-03 11:39:32,469 INFO org.apache.hadoop.yarn.server.resourcemanager.amlauncher.AMLauncher: Command to launch container container_1483412440498_0003_01_000001 : $JAVA_HOME/bin/java -Djava.io.tmpdir=$PWD/tmp -Dlog4j.configuration=container-log4j.properties -Dyarn.app.container.log.dir=<LOG_DIR> -Dyarn.app.container.log.filesize=0 -Dhadoop.root.logger=INFO,CLA -Dhadoop.root.logfile=syslog  -Xmx1024m org.apache.hadoop.mapreduce.v2.app.MRAppMaster 1><LOG_DIR>/stdout 2><LOG_DIR>/stderr 
2017-01-03 11:39:32,470 INFO org.apache.hadoop.yarn.server.resourcemanager.security.AMRMTokenSecretManager: Create AMRMToken for ApplicationAttempt: appattempt_1483412440498_0003_000001
2017-01-03 11:39:32,470 INFO org.apache.hadoop.yarn.server.resourcemanager.security.AMRMTokenSecretManager: Creating password for appattempt_1483412440498_0003_000001
2017-01-03 11:39:32,490 INFO org.apache.hadoop.yarn.server.resourcemanager.amlauncher.AMLauncher: Done launching container Container: [ContainerId: container_1483412440498_0003_01_000001, NodeId: tfs03:45427, NodeHttpAddress: tfs03:8042, Resource: <memory:2048, vCores:1>, Priority: 0, Token: Token { kind: ContainerToken, service: 192.168.50.13:45427 }, ] for AM appattempt_1483412440498_0003_000001
2017-01-03 11:39:32,490 INFO org.apache.hadoop.yarn.server.resourcemanager.rmapp.attempt.RMAppAttemptImpl: appattempt_1483412440498_0003_000001 State change from ALLOCATED to LAUNCHED
2017-01-03 11:39:33,247 INFO org.apache.hadoop.yarn.server.resourcemanager.rmcontainer.RMContainerImpl: container_1483412440498_0003_01_000001 Container Transitioned from ACQUIRED to RUNNING
2017-01-03 11:39:40,365 INFO SecurityLogger.org.apache.hadoop.ipc.Server: Auth successful for appattempt_1483412440498_0003_000001 (auth:SIMPLE)
2017-01-03 11:39:40,370 INFO org.apache.hadoop.yarn.server.resourcemanager.ApplicationMasterService: AM registration appattempt_1483412440498_0003_000001
2017-01-03 11:39:40,370 INFO org.apache.hadoop.yarn.server.resourcemanager.RMAuditLogger: USER=root	IP=192.168.50.13	OPERATION=Register App Master	TARGET=ApplicationMasterService	RESULT=SUCCESS	APPID=application_1483412440498_0003	APPATTEMPTID=appattempt_1483412440498_0003_000001
2017-01-03 11:39:40,370 INFO org.apache.hadoop.yarn.server.resourcemanager.rmapp.attempt.RMAppAttemptImpl: appattempt_1483412440498_0003_000001 State change from LAUNCHED to RUNNING
2017-01-03 11:39:40,370 INFO org.apache.hadoop.yarn.server.resourcemanager.rmapp.RMAppImpl: application_1483412440498_0003 State change from ACCEPTED to RUNNING
2017-01-03 11:39:42,256 INFO org.apache.hadoop.yarn.server.resourcemanager.rmcontainer.RMContainerImpl: container_1483412440498_0003_01_000002 Container Transitioned from NEW to ALLOCATED
2017-01-03 11:39:42,256 INFO org.apache.hadoop.yarn.server.resourcemanager.RMAuditLogger: USER=root	OPERATION=AM Allocated Container	TARGET=SchedulerApp	RESULT=SUCCESS	APPID=application_1483412440498_0003	CONTAINERID=container_1483412440498_0003_01_000002
2017-01-03 11:39:42,256 INFO org.apache.hadoop.yarn.server.resourcemanager.scheduler.SchedulerNode: Assigned container container_1483412440498_0003_01_000002 of capacity <memory:1024, vCores:1> on host tfs03:45427, which has 2 containers, <memory:3072, vCores:2> used and <memory:5120, vCores:6> available after allocation
2017-01-03 11:39:42,256 INFO org.apache.hadoop.yarn.server.resourcemanager.scheduler.capacity.LeafQueue: assignedContainer application attempt=appattempt_1483412440498_0003_000001 container=Container: [ContainerId: container_1483412440498_0003_01_000002, NodeId: tfs03:45427, NodeHttpAddress: tfs03:8042, Resource: <memory:1024, vCores:1>, Priority: 20, Token: null, ] queue=default: capacity=1.0, absoluteCapacity=1.0, usedResources=<memory:2048, vCores:1>, usedCapacity=0.125, absoluteUsedCapacity=0.125, numApps=1, numContainers=1 clusterResource=<memory:16384, vCores:16> type=NODE_LOCAL
2017-01-03 11:39:42,257 INFO org.apache.hadoop.yarn.server.resourcemanager.scheduler.capacity.ParentQueue: Re-sorting assigned queue: root.default stats: default: capacity=1.0, absoluteCapacity=1.0, usedResources=<memory:3072, vCores:2>, usedCapacity=0.1875, absoluteUsedCapacity=0.1875, numApps=1, numContainers=2
2017-01-03 11:39:42,257 INFO org.apache.hadoop.yarn.server.resourcemanager.scheduler.capacity.ParentQueue: assignedContainer queue=root usedCapacity=0.1875 absoluteUsedCapacity=0.1875 used=<memory:3072, vCores:2> cluster=<memory:16384, vCores:16>
2017-01-03 11:39:42,257 INFO org.apache.hadoop.yarn.server.resourcemanager.rmcontainer.RMContainerImpl: container_1483412440498_0003_01_000003 Container Transitioned from NEW to ALLOCATED
2017-01-03 11:39:42,257 INFO org.apache.hadoop.yarn.server.resourcemanager.RMAuditLogger: USER=root	OPERATION=AM Allocated Container	TARGET=SchedulerApp	RESULT=SUCCESS	APPID=application_1483412440498_0003	CONTAINERID=container_1483412440498_0003_01_000003
2017-01-03 11:39:42,257 INFO org.apache.hadoop.yarn.server.resourcemanager.scheduler.SchedulerNode: Assigned container container_1483412440498_0003_01_000003 of capacity <memory:1024, vCores:1> on host tfs03:45427, which has 3 containers, <memory:4096, vCores:3> used and <memory:4096, vCores:5> available after allocation
2017-01-03 11:39:42,257 INFO org.apache.hadoop.yarn.server.resourcemanager.scheduler.capacity.LeafQueue: assignedContainer application attempt=appattempt_1483412440498_0003_000001 container=Container: [ContainerId: container_1483412440498_0003_01_000003, NodeId: tfs03:45427, NodeHttpAddress: tfs03:8042, Resource: <memory:1024, vCores:1>, Priority: 20, Token: null, ] queue=default: capacity=1.0, absoluteCapacity=1.0, usedResources=<memory:3072, vCores:2>, usedCapacity=0.1875, absoluteUsedCapacity=0.1875, numApps=1, numContainers=2 clusterResource=<memory:16384, vCores:16> type=NODE_LOCAL
2017-01-03 11:39:42,258 INFO org.apache.hadoop.yarn.server.resourcemanager.scheduler.capacity.ParentQueue: Re-sorting assigned queue: root.default stats: default: capacity=1.0, absoluteCapacity=1.0, usedResources=<memory:4096, vCores:3>, usedCapacity=0.25, absoluteUsedCapacity=0.25, numApps=1, numContainers=3
2017-01-03 11:39:42,258 INFO org.apache.hadoop.yarn.server.resourcemanager.scheduler.capacity.ParentQueue: assignedContainer queue=root usedCapacity=0.25 absoluteUsedCapacity=0.25 used=<memory:4096, vCores:3> cluster=<memory:16384, vCores:16>
2017-01-03 11:39:42,436 INFO org.apache.hadoop.yarn.server.resourcemanager.security.NMTokenSecretManagerInRM: Sending NMToken for nodeId : tfs03:45427 for container : container_1483412440498_0003_01_000002
2017-01-03 11:39:42,438 INFO org.apache.hadoop.yarn.server.resourcemanager.rmcontainer.RMContainerImpl: container_1483412440498_0003_01_000002 Container Transitioned from ALLOCATED to ACQUIRED
2017-01-03 11:39:42,440 INFO org.apache.hadoop.yarn.server.resourcemanager.rmcontainer.RMContainerImpl: container_1483412440498_0003_01_000003 Container Transitioned from ALLOCATED to ACQUIRED
2017-01-03 11:39:43,257 INFO org.apache.hadoop.yarn.server.resourcemanager.rmcontainer.RMContainerImpl: container_1483412440498_0003_01_000004 Container Transitioned from NEW to ALLOCATED
2017-01-03 11:39:43,258 INFO org.apache.hadoop.yarn.server.resourcemanager.RMAuditLogger: USER=root	OPERATION=AM Allocated Container	TARGET=SchedulerApp	RESULT=SUCCESS	APPID=application_1483412440498_0003	CONTAINERID=container_1483412440498_0003_01_000004
2017-01-03 11:39:43,258 INFO org.apache.hadoop.yarn.server.resourcemanager.scheduler.SchedulerNode: Assigned container container_1483412440498_0003_01_000004 of capacity <memory:1024, vCores:1> on host tfs03:45427, which has 4 containers, <memory:5120, vCores:4> used and <memory:3072, vCores:4> available after allocation
2017-01-03 11:39:43,258 INFO org.apache.hadoop.yarn.server.resourcemanager.scheduler.capacity.LeafQueue: assignedContainer application attempt=appattempt_1483412440498_0003_000001 container=Container: [ContainerId: container_1483412440498_0003_01_000004, NodeId: tfs03:45427, NodeHttpAddress: tfs03:8042, Resource: <memory:1024, vCores:1>, Priority: 20, Token: null, ] queue=default: capacity=1.0, absoluteCapacity=1.0, usedResources=<memory:4096, vCores:3>, usedCapacity=0.25, absoluteUsedCapacity=0.25, numApps=1, numContainers=3 clusterResource=<memory:16384, vCores:16> type=RACK_LOCAL
2017-01-03 11:39:43,258 INFO org.apache.hadoop.yarn.server.resourcemanager.scheduler.capacity.ParentQueue: Re-sorting assigned queue: root.default stats: default: capacity=1.0, absoluteCapacity=1.0, usedResources=<memory:5120, vCores:4>, usedCapacity=0.3125, absoluteUsedCapacity=0.3125, numApps=1, numContainers=4
2017-01-03 11:39:43,258 INFO org.apache.hadoop.yarn.server.resourcemanager.scheduler.capacity.ParentQueue: assignedContainer queue=root usedCapacity=0.3125 absoluteUsedCapacity=0.3125 used=<memory:5120, vCores:4> cluster=<memory:16384, vCores:16>
2017-01-03 11:39:43,463 INFO org.apache.hadoop.yarn.server.resourcemanager.rmcontainer.RMContainerImpl: container_1483412440498_0003_01_000004 Container Transitioned from ALLOCATED to ACQUIRED
2017-01-03 11:39:44,259 INFO org.apache.hadoop.yarn.server.resourcemanager.rmcontainer.RMContainerImpl: container_1483412440498_0003_01_000002 Container Transitioned from ACQUIRED to RUNNING
2017-01-03 11:39:44,260 INFO org.apache.hadoop.yarn.server.resourcemanager.rmcontainer.RMContainerImpl: container_1483412440498_0003_01_000003 Container Transitioned from ACQUIRED to RUNNING
2017-01-03 11:39:44,260 INFO org.apache.hadoop.yarn.server.resourcemanager.rmcontainer.RMContainerImpl: container_1483412440498_0003_01_000004 Container Transitioned from ACQUIRED to RUNNING
2017-01-03 11:39:44,261 INFO org.apache.hadoop.yarn.server.resourcemanager.rmcontainer.RMContainerImpl: container_1483412440498_0003_01_000005 Container Transitioned from NEW to ALLOCATED
2017-01-03 11:39:44,261 INFO org.apache.hadoop.yarn.server.resourcemanager.RMAuditLogger: USER=root	OPERATION=AM Allocated Container	TARGET=SchedulerApp	RESULT=SUCCESS	APPID=application_1483412440498_0003	CONTAINERID=container_1483412440498_0003_01_000005
2017-01-03 11:39:44,261 INFO org.apache.hadoop.yarn.server.resourcemanager.scheduler.SchedulerNode: Assigned container container_1483412440498_0003_01_000005 of capacity <memory:1024, vCores:1> on host tfs03:45427, which has 5 containers, <memory:6144, vCores:5> used and <memory:2048, vCores:3> available after allocation
2017-01-03 11:39:44,261 INFO org.apache.hadoop.yarn.server.resourcemanager.scheduler.capacity.LeafQueue: assignedContainer application attempt=appattempt_1483412440498_0003_000001 container=Container: [ContainerId: container_1483412440498_0003_01_000005, NodeId: tfs03:45427, NodeHttpAddress: tfs03:8042, Resource: <memory:1024, vCores:1>, Priority: 20, Token: null, ] queue=default: capacity=1.0, absoluteCapacity=1.0, usedResources=<memory:5120, vCores:4>, usedCapacity=0.3125, absoluteUsedCapacity=0.3125, numApps=1, numContainers=4 clusterResource=<memory:16384, vCores:16> type=RACK_LOCAL
2017-01-03 11:39:44,261 INFO org.apache.hadoop.yarn.server.resourcemanager.scheduler.capacity.ParentQueue: Re-sorting assigned queue: root.default stats: default: capacity=1.0, absoluteCapacity=1.0, usedResources=<memory:6144, vCores:5>, usedCapacity=0.375, absoluteUsedCapacity=0.375, numApps=1, numContainers=5
2017-01-03 11:39:44,262 INFO org.apache.hadoop.yarn.server.resourcemanager.scheduler.capacity.ParentQueue: assignedContainer queue=root usedCapacity=0.375 absoluteUsedCapacity=0.375 used=<memory:6144, vCores:5> cluster=<memory:16384, vCores:16>
2017-01-03 11:39:44,471 INFO org.apache.hadoop.yarn.server.resourcemanager.rmcontainer.RMContainerImpl: container_1483412440498_0003_01_000005 Container Transitioned from ALLOCATED to ACQUIRED
2017-01-03 11:39:44,618 INFO org.apache.hadoop.yarn.server.resourcemanager.rmcontainer.RMContainerImpl: container_1483412440498_0003_01_000006 Container Transitioned from NEW to ALLOCATED
2017-01-03 11:39:44,618 INFO org.apache.hadoop.yarn.server.resourcemanager.RMAuditLogger: USER=root	OPERATION=AM Allocated Container	TARGET=SchedulerApp	RESULT=SUCCESS	APPID=application_1483412440498_0003	CONTAINERID=container_1483412440498_0003_01_000006
2017-01-03 11:39:44,619 INFO org.apache.hadoop.yarn.server.resourcemanager.scheduler.SchedulerNode: Assigned container container_1483412440498_0003_01_000006 of capacity <memory:1024, vCores:1> on host tfs04:38559, which has 1 containers, <memory:1024, vCores:1> used and <memory:7168, vCores:7> available after allocation
2017-01-03 11:39:44,619 INFO org.apache.hadoop.yarn.server.resourcemanager.scheduler.capacity.LeafQueue: assignedContainer application attempt=appattempt_1483412440498_0003_000001 container=Container: [ContainerId: container_1483412440498_0003_01_000006, NodeId: tfs04:38559, NodeHttpAddress: tfs04:8042, Resource: <memory:1024, vCores:1>, Priority: 20, Token: null, ] queue=default: capacity=1.0, absoluteCapacity=1.0, usedResources=<memory:6144, vCores:5>, usedCapacity=0.375, absoluteUsedCapacity=0.375, numApps=1, numContainers=5 clusterResource=<memory:16384, vCores:16> type=OFF_SWITCH
2017-01-03 11:39:44,619 INFO org.apache.hadoop.yarn.server.resourcemanager.scheduler.capacity.ParentQueue: Re-sorting assigned queue: root.default stats: default: capacity=1.0, absoluteCapacity=1.0, usedResources=<memory:7168, vCores:6>, usedCapacity=0.4375, absoluteUsedCapacity=0.4375, numApps=1, numContainers=6
2017-01-03 11:39:44,619 INFO org.apache.hadoop.yarn.server.resourcemanager.scheduler.capacity.ParentQueue: assignedContainer queue=root usedCapacity=0.4375 absoluteUsedCapacity=0.4375 used=<memory:7168, vCores:6> cluster=<memory:16384, vCores:16>
2017-01-03 11:39:45,264 INFO org.apache.hadoop.yarn.server.resourcemanager.rmcontainer.RMContainerImpl: container_1483412440498_0003_01_000005 Container Transitioned from ACQUIRED to RUNNING
2017-01-03 11:39:45,476 INFO org.apache.hadoop.yarn.server.resourcemanager.scheduler.AppSchedulingInfo: checking for deactivate of application :application_1483412440498_0003
2017-01-03 11:39:45,479 INFO org.apache.hadoop.yarn.server.resourcemanager.security.NMTokenSecretManagerInRM: Sending NMToken for nodeId : tfs04:38559 for container : container_1483412440498_0003_01_000006
2017-01-03 11:39:45,480 INFO org.apache.hadoop.yarn.server.resourcemanager.rmcontainer.RMContainerImpl: container_1483412440498_0003_01_000006 Container Transitioned from ALLOCATED to ACQUIRED
2017-01-03 11:39:46,484 INFO org.apache.hadoop.yarn.server.resourcemanager.rmcontainer.RMContainerImpl: container_1483412440498_0003_01_000006 Container Transitioned from ACQUIRED to RELEASED
2017-01-03 11:39:46,485 INFO org.apache.hadoop.yarn.server.resourcemanager.scheduler.common.fica.FiCaSchedulerApp: Completed container: container_1483412440498_0003_01_000006 in state: RELEASED event:RELEASED
2017-01-03 11:39:46,485 INFO org.apache.hadoop.yarn.server.resourcemanager.RMAuditLogger: USER=root	IP=192.168.50.13	OPERATION=AM Released Container	TARGET=SchedulerApp	RESULT=SUCCESS	APPID=application_1483412440498_0003	CONTAINERID=container_1483412440498_0003_01_000006
2017-01-03 11:39:46,485 INFO org.apache.hadoop.yarn.server.resourcemanager.scheduler.SchedulerNode: Released container container_1483412440498_0003_01_000006 of capacity <memory:1024, vCores:1> on host tfs04:38559, which currently has 0 containers, <memory:0, vCores:0> used and <memory:8192, vCores:8> available, release resources=true
2017-01-03 11:39:46,486 INFO org.apache.hadoop.yarn.server.resourcemanager.scheduler.capacity.LeafQueue: default used=<memory:6144, vCores:5> numContainers=5 user=root user-resources=<memory:6144, vCores:5>
2017-01-03 11:39:46,486 INFO org.apache.hadoop.yarn.server.resourcemanager.scheduler.capacity.LeafQueue: completedContainer container=Container: [ContainerId: container_1483412440498_0003_01_000006, NodeId: tfs04:38559, NodeHttpAddress: tfs04:8042, Resource: <memory:1024, vCores:1>, Priority: 20, Token: Token { kind: ContainerToken, service: 192.168.50.14:38559 }, ] queue=default: capacity=1.0, absoluteCapacity=1.0, usedResources=<memory:6144, vCores:5>, usedCapacity=0.375, absoluteUsedCapacity=0.375, numApps=1, numContainers=5 cluster=<memory:16384, vCores:16>
2017-01-03 11:39:46,486 INFO org.apache.hadoop.yarn.server.resourcemanager.scheduler.capacity.ParentQueue: completedContainer queue=root usedCapacity=0.375 absoluteUsedCapacity=0.375 used=<memory:6144, vCores:5> cluster=<memory:16384, vCores:16>
2017-01-03 11:39:46,486 INFO org.apache.hadoop.yarn.server.resourcemanager.scheduler.capacity.ParentQueue: Re-sorting completed queue: root.default stats: default: capacity=1.0, absoluteCapacity=1.0, usedResources=<memory:6144, vCores:5>, usedCapacity=0.375, absoluteUsedCapacity=0.375, numApps=1, numContainers=5
2017-01-03 11:39:46,487 INFO org.apache.hadoop.yarn.server.resourcemanager.scheduler.capacity.CapacityScheduler: Application attempt appattempt_1483412440498_0003_000001 released container container_1483412440498_0003_01_000006 on node: host: tfs04:38559 #containers=0 available=<memory:8192, vCores:8> used=<memory:0, vCores:0> with event: RELEASED
2017-01-03 11:39:58,352 INFO org.apache.hadoop.yarn.server.resourcemanager.rmcontainer.RMContainerImpl: container_1483412440498_0003_01_000003 Container Transitioned from RUNNING to COMPLETED
2017-01-03 11:39:58,352 INFO org.apache.hadoop.yarn.server.resourcemanager.scheduler.common.fica.FiCaSchedulerApp: Completed container: container_1483412440498_0003_01_000003 in state: COMPLETED event:FINISHED
2017-01-03 11:39:58,352 INFO org.apache.hadoop.yarn.server.resourcemanager.RMAuditLogger: USER=root	OPERATION=AM Released Container	TARGET=SchedulerApp	RESULT=SUCCESS	APPID=application_1483412440498_0003	CONTAINERID=container_1483412440498_0003_01_000003
2017-01-03 11:39:58,352 INFO org.apache.hadoop.yarn.server.resourcemanager.scheduler.SchedulerNode: Released container container_1483412440498_0003_01_000003 of capacity <memory:1024, vCores:1> on host tfs03:45427, which currently has 4 containers, <memory:5120, vCores:4> used and <memory:3072, vCores:4> available, release resources=true
2017-01-03 11:39:58,353 INFO org.apache.hadoop.yarn.server.resourcemanager.scheduler.capacity.LeafQueue: default used=<memory:5120, vCores:4> numContainers=4 user=root user-resources=<memory:5120, vCores:4>
2017-01-03 11:39:58,353 INFO org.apache.hadoop.yarn.server.resourcemanager.scheduler.capacity.LeafQueue: completedContainer container=Container: [ContainerId: container_1483412440498_0003_01_000003, NodeId: tfs03:45427, NodeHttpAddress: tfs03:8042, Resource: <memory:1024, vCores:1>, Priority: 20, Token: Token { kind: ContainerToken, service: 192.168.50.13:45427 }, ] queue=default: capacity=1.0, absoluteCapacity=1.0, usedResources=<memory:5120, vCores:4>, usedCapacity=0.3125, absoluteUsedCapacity=0.3125, numApps=1, numContainers=4 cluster=<memory:16384, vCores:16>
2017-01-03 11:39:58,353 INFO org.apache.hadoop.yarn.server.resourcemanager.scheduler.capacity.ParentQueue: completedContainer queue=root usedCapacity=0.3125 absoluteUsedCapacity=0.3125 used=<memory:5120, vCores:4> cluster=<memory:16384, vCores:16>
2017-01-03 11:39:58,354 INFO org.apache.hadoop.yarn.server.resourcemanager.scheduler.capacity.ParentQueue: Re-sorting completed queue: root.default stats: default: capacity=1.0, absoluteCapacity=1.0, usedResources=<memory:5120, vCores:4>, usedCapacity=0.3125, absoluteUsedCapacity=0.3125, numApps=1, numContainers=4
2017-01-03 11:39:58,354 INFO org.apache.hadoop.yarn.server.resourcemanager.scheduler.capacity.CapacityScheduler: Application attempt appattempt_1483412440498_0003_000001 released container container_1483412440498_0003_01_000003 on node: host: tfs03:45427 #containers=4 available=<memory:3072, vCores:4> used=<memory:5120, vCores:4> with event: FINISHED
2017-01-03 11:39:58,635 INFO org.apache.hadoop.yarn.server.resourcemanager.rmcontainer.RMContainerImpl: container_1483412440498_0003_01_000007 Container Transitioned from NEW to ALLOCATED
2017-01-03 11:39:58,635 INFO org.apache.hadoop.yarn.server.resourcemanager.RMAuditLogger: USER=root	OPERATION=AM Allocated Container	TARGET=SchedulerApp	RESULT=SUCCESS	APPID=application_1483412440498_0003	CONTAINERID=container_1483412440498_0003_01_000007
2017-01-03 11:39:58,635 INFO org.apache.hadoop.yarn.server.resourcemanager.scheduler.SchedulerNode: Assigned container container_1483412440498_0003_01_000007 of capacity <memory:1024, vCores:1> on host tfs04:38559, which has 1 containers, <memory:1024, vCores:1> used and <memory:7168, vCores:7> available after allocation
2017-01-03 11:39:58,635 INFO org.apache.hadoop.yarn.server.resourcemanager.scheduler.capacity.LeafQueue: assignedContainer application attempt=appattempt_1483412440498_0003_000001 container=Container: [ContainerId: container_1483412440498_0003_01_000007, NodeId: tfs04:38559, NodeHttpAddress: tfs04:8042, Resource: <memory:1024, vCores:1>, Priority: 20, Token: null, ] queue=default: capacity=1.0, absoluteCapacity=1.0, usedResources=<memory:5120, vCores:4>, usedCapacity=0.3125, absoluteUsedCapacity=0.3125, numApps=1, numContainers=4 clusterResource=<memory:16384, vCores:16> type=RACK_LOCAL
2017-01-03 11:39:58,636 INFO org.apache.hadoop.yarn.server.resourcemanager.scheduler.capacity.ParentQueue: Re-sorting assigned queue: root.default stats: default: capacity=1.0, absoluteCapacity=1.0, usedResources=<memory:6144, vCores:5>, usedCapacity=0.375, absoluteUsedCapacity=0.375, numApps=1, numContainers=5
2017-01-03 11:39:58,636 INFO org.apache.hadoop.yarn.server.resourcemanager.scheduler.capacity.ParentQueue: assignedContainer queue=root usedCapacity=0.375 absoluteUsedCapacity=0.375 used=<memory:6144, vCores:5> cluster=<memory:16384, vCores:16>
2017-01-03 11:39:59,537 INFO org.apache.hadoop.yarn.server.resourcemanager.rmcontainer.RMContainerImpl: container_1483412440498_0003_01_000007 Container Transitioned from ALLOCATED to ACQUIRED
2017-01-03 11:39:59,635 INFO org.apache.hadoop.yarn.server.resourcemanager.rmcontainer.RMContainerImpl: container_1483412440498_0003_01_000007 Container Transitioned from ACQUIRED to RUNNING
2017-01-03 11:39:59,636 INFO org.apache.hadoop.yarn.server.resourcemanager.rmcontainer.RMContainerImpl: container_1483412440498_0003_01_000008 Container Transitioned from NEW to ALLOCATED
2017-01-03 11:39:59,636 INFO org.apache.hadoop.yarn.server.resourcemanager.RMAuditLogger: USER=root	OPERATION=AM Allocated Container	TARGET=SchedulerApp	RESULT=SUCCESS	APPID=application_1483412440498_0003	CONTAINERID=container_1483412440498_0003_01_000008
2017-01-03 11:39:59,636 INFO org.apache.hadoop.yarn.server.resourcemanager.scheduler.SchedulerNode: Assigned container container_1483412440498_0003_01_000008 of capacity <memory:1024, vCores:1> on host tfs04:38559, which has 2 containers, <memory:2048, vCores:2> used and <memory:6144, vCores:6> available after allocation
2017-01-03 11:39:59,636 INFO org.apache.hadoop.yarn.server.resourcemanager.scheduler.capacity.LeafQueue: assignedContainer application attempt=appattempt_1483412440498_0003_000001 container=Container: [ContainerId: container_1483412440498_0003_01_000008, NodeId: tfs04:38559, NodeHttpAddress: tfs04:8042, Resource: <memory:1024, vCores:1>, Priority: 10, Token: null, ] queue=default: capacity=1.0, absoluteCapacity=1.0, usedResources=<memory:6144, vCores:5>, usedCapacity=0.375, absoluteUsedCapacity=0.375, numApps=1, numContainers=5 clusterResource=<memory:16384, vCores:16> type=OFF_SWITCH
2017-01-03 11:39:59,636 INFO org.apache.hadoop.yarn.server.resourcemanager.scheduler.capacity.ParentQueue: Re-sorting assigned queue: root.default stats: default: capacity=1.0, absoluteCapacity=1.0, usedResources=<memory:7168, vCores:6>, usedCapacity=0.4375, absoluteUsedCapacity=0.4375, numApps=1, numContainers=6
2017-01-03 11:39:59,636 INFO org.apache.hadoop.yarn.server.resourcemanager.scheduler.capacity.ParentQueue: assignedContainer queue=root usedCapacity=0.4375 absoluteUsedCapacity=0.4375 used=<memory:7168, vCores:6> cluster=<memory:16384, vCores:16>
2017-01-03 11:40:00,353 INFO org.apache.hadoop.yarn.server.resourcemanager.rmcontainer.RMContainerImpl: container_1483412440498_0003_01_000009 Container Transitioned from NEW to ALLOCATED
2017-01-03 11:40:00,354 INFO org.apache.hadoop.yarn.server.resourcemanager.RMAuditLogger: USER=root	OPERATION=AM Allocated Container	TARGET=SchedulerApp	RESULT=SUCCESS	APPID=application_1483412440498_0003	CONTAINERID=container_1483412440498_0003_01_000009
2017-01-03 11:40:00,354 INFO org.apache.hadoop.yarn.server.resourcemanager.scheduler.SchedulerNode: Assigned container container_1483412440498_0003_01_000009 of capacity <memory:1024, vCores:1> on host tfs03:45427, which has 5 containers, <memory:6144, vCores:5> used and <memory:2048, vCores:3> available after allocation
2017-01-03 11:40:00,354 INFO org.apache.hadoop.yarn.server.resourcemanager.scheduler.capacity.LeafQueue: assignedContainer application attempt=appattempt_1483412440498_0003_000001 container=Container: [ContainerId: container_1483412440498_0003_01_000009, NodeId: tfs03:45427, NodeHttpAddress: tfs03:8042, Resource: <memory:1024, vCores:1>, Priority: 10, Token: null, ] queue=default: capacity=1.0, absoluteCapacity=1.0, usedResources=<memory:7168, vCores:6>, usedCapacity=0.4375, absoluteUsedCapacity=0.4375, numApps=1, numContainers=6 clusterResource=<memory:16384, vCores:16> type=OFF_SWITCH
2017-01-03 11:40:00,354 INFO org.apache.hadoop.yarn.server.resourcemanager.scheduler.capacity.ParentQueue: Re-sorting assigned queue: root.default stats: default: capacity=1.0, absoluteCapacity=1.0, usedResources=<memory:8192, vCores:7>, usedCapacity=0.5, absoluteUsedCapacity=0.5, numApps=1, numContainers=7
2017-01-03 11:40:00,354 INFO org.apache.hadoop.yarn.server.resourcemanager.scheduler.capacity.ParentQueue: assignedContainer queue=root usedCapacity=0.5 absoluteUsedCapacity=0.5 used=<memory:8192, vCores:7> cluster=<memory:16384, vCores:16>
2017-01-03 11:40:00,544 INFO org.apache.hadoop.yarn.server.resourcemanager.scheduler.AppSchedulingInfo: checking for deactivate of application :application_1483412440498_0003
2017-01-03 11:40:00,547 INFO org.apache.hadoop.yarn.server.resourcemanager.rmcontainer.RMContainerImpl: container_1483412440498_0003_01_000008 Container Transitioned from ALLOCATED to ACQUIRED
2017-01-03 11:40:00,548 INFO org.apache.hadoop.yarn.server.resourcemanager.rmcontainer.RMContainerImpl: container_1483412440498_0003_01_000009 Container Transitioned from ALLOCATED to ACQUIRED
2017-01-03 11:40:00,637 INFO org.apache.hadoop.yarn.server.resourcemanager.rmcontainer.RMContainerImpl: container_1483412440498_0003_01_000008 Container Transitioned from ACQUIRED to RUNNING
2017-01-03 11:40:00,637 INFO org.apache.hadoop.yarn.server.resourcemanager.rmcontainer.RMContainerImpl: container_1483412440498_0003_01_000010 Container Transitioned from NEW to ALLOCATED
2017-01-03 11:40:00,637 INFO org.apache.hadoop.yarn.server.resourcemanager.RMAuditLogger: USER=root	OPERATION=AM Allocated Container	TARGET=SchedulerApp	RESULT=SUCCESS	APPID=application_1483412440498_0003	CONTAINERID=container_1483412440498_0003_01_000010
2017-01-03 11:40:00,637 INFO org.apache.hadoop.yarn.server.resourcemanager.scheduler.SchedulerNode: Assigned container container_1483412440498_0003_01_000010 of capacity <memory:1024, vCores:1> on host tfs04:38559, which has 3 containers, <memory:3072, vCores:3> used and <memory:5120, vCores:5> available after allocation
2017-01-03 11:40:00,638 INFO org.apache.hadoop.yarn.server.resourcemanager.scheduler.capacity.LeafQueue: assignedContainer application attempt=appattempt_1483412440498_0003_000001 container=Container: [ContainerId: container_1483412440498_0003_01_000010, NodeId: tfs04:38559, NodeHttpAddress: tfs04:8042, Resource: <memory:1024, vCores:1>, Priority: 10, Token: null, ] queue=default: capacity=1.0, absoluteCapacity=1.0, usedResources=<memory:8192, vCores:7>, usedCapacity=0.5, absoluteUsedCapacity=0.5, numApps=1, numContainers=7 clusterResource=<memory:16384, vCores:16> type=OFF_SWITCH
2017-01-03 11:40:00,638 INFO org.apache.hadoop.yarn.server.resourcemanager.scheduler.capacity.ParentQueue: Re-sorting assigned queue: root.default stats: default: capacity=1.0, absoluteCapacity=1.0, usedResources=<memory:9216, vCores:8>, usedCapacity=0.5625, absoluteUsedCapacity=0.5625, numApps=1, numContainers=8
2017-01-03 11:40:00,638 INFO org.apache.hadoop.yarn.server.resourcemanager.scheduler.capacity.ParentQueue: assignedContainer queue=root usedCapacity=0.5625 absoluteUsedCapacity=0.5625 used=<memory:9216, vCores:8> cluster=<memory:16384, vCores:16>
2017-01-03 11:40:01,355 INFO org.apache.hadoop.yarn.server.resourcemanager.rmcontainer.RMContainerImpl: container_1483412440498_0003_01_000009 Container Transitioned from ACQUIRED to RUNNING
2017-01-03 11:40:01,358 INFO org.apache.hadoop.yarn.server.resourcemanager.rmcontainer.RMContainerImpl: container_1483412440498_0003_01_000011 Container Transitioned from NEW to ALLOCATED
2017-01-03 11:40:01,358 INFO org.apache.hadoop.yarn.server.resourcemanager.RMAuditLogger: USER=root	OPERATION=AM Allocated Container	TARGET=SchedulerApp	RESULT=SUCCESS	APPID=application_1483412440498_0003	CONTAINERID=container_1483412440498_0003_01_000011
2017-01-03 11:40:01,358 INFO org.apache.hadoop.yarn.server.resourcemanager.scheduler.SchedulerNode: Assigned container container_1483412440498_0003_01_000011 of capacity <memory:1024, vCores:1> on host tfs03:45427, which has 6 containers, <memory:7168, vCores:6> used and <memory:1024, vCores:2> available after allocation
2017-01-03 11:40:01,358 INFO org.apache.hadoop.yarn.server.resourcemanager.scheduler.capacity.LeafQueue: assignedContainer application attempt=appattempt_1483412440498_0003_000001 container=Container: [ContainerId: container_1483412440498_0003_01_000011, NodeId: tfs03:45427, NodeHttpAddress: tfs03:8042, Resource: <memory:1024, vCores:1>, Priority: 10, Token: null, ] queue=default: capacity=1.0, absoluteCapacity=1.0, usedResources=<memory:9216, vCores:8>, usedCapacity=0.5625, absoluteUsedCapacity=0.5625, numApps=1, numContainers=8 clusterResource=<memory:16384, vCores:16> type=OFF_SWITCH
2017-01-03 11:40:01,358 INFO org.apache.hadoop.yarn.server.resourcemanager.scheduler.capacity.ParentQueue: Re-sorting assigned queue: root.default stats: default: capacity=1.0, absoluteCapacity=1.0, usedResources=<memory:10240, vCores:9>, usedCapacity=0.625, absoluteUsedCapacity=0.625, numApps=1, numContainers=9
2017-01-03 11:40:01,359 INFO org.apache.hadoop.yarn.server.resourcemanager.scheduler.capacity.ParentQueue: assignedContainer queue=root usedCapacity=0.625 absoluteUsedCapacity=0.625 used=<memory:10240, vCores:9> cluster=<memory:16384, vCores:16>
2017-01-03 11:40:01,559 INFO org.apache.hadoop.yarn.server.resourcemanager.rmcontainer.RMContainerImpl: container_1483412440498_0003_01_000010 Container Transitioned from ALLOCATED to ACQUIRED
2017-01-03 11:40:01,561 INFO org.apache.hadoop.yarn.server.resourcemanager.rmcontainer.RMContainerImpl: container_1483412440498_0003_01_000011 Container Transitioned from ALLOCATED to ACQUIRED
2017-01-03 11:40:01,638 INFO org.apache.hadoop.yarn.server.resourcemanager.rmcontainer.RMContainerImpl: container_1483412440498_0003_01_000010 Container Transitioned from ACQUIRED to RUNNING
2017-01-03 11:40:01,639 INFO org.apache.hadoop.yarn.server.resourcemanager.rmcontainer.RMContainerImpl: container_1483412440498_0003_01_000012 Container Transitioned from NEW to ALLOCATED
2017-01-03 11:40:01,639 INFO org.apache.hadoop.yarn.server.resourcemanager.RMAuditLogger: USER=root	OPERATION=AM Allocated Container	TARGET=SchedulerApp	RESULT=SUCCESS	APPID=application_1483412440498_0003	CONTAINERID=container_1483412440498_0003_01_000012
2017-01-03 11:40:01,639 INFO org.apache.hadoop.yarn.server.resourcemanager.scheduler.SchedulerNode: Assigned container container_1483412440498_0003_01_000012 of capacity <memory:1024, vCores:1> on host tfs04:38559, which has 4 containers, <memory:4096, vCores:4> used and <memory:4096, vCores:4> available after allocation
2017-01-03 11:40:01,639 INFO org.apache.hadoop.yarn.server.resourcemanager.scheduler.capacity.LeafQueue: assignedContainer application attempt=appattempt_1483412440498_0003_000001 container=Container: [ContainerId: container_1483412440498_0003_01_000012, NodeId: tfs04:38559, NodeHttpAddress: tfs04:8042, Resource: <memory:1024, vCores:1>, Priority: 10, Token: null, ] queue=default: capacity=1.0, absoluteCapacity=1.0, usedResources=<memory:10240, vCores:9>, usedCapacity=0.625, absoluteUsedCapacity=0.625, numApps=1, numContainers=9 clusterResource=<memory:16384, vCores:16> type=OFF_SWITCH
2017-01-03 11:40:01,639 INFO org.apache.hadoop.yarn.server.resourcemanager.scheduler.capacity.ParentQueue: Re-sorting assigned queue: root.default stats: default: capacity=1.0, absoluteCapacity=1.0, usedResources=<memory:11264, vCores:10>, usedCapacity=0.6875, absoluteUsedCapacity=0.6875, numApps=1, numContainers=10
2017-01-03 11:40:01,639 INFO org.apache.hadoop.yarn.server.resourcemanager.scheduler.capacity.ParentQueue: assignedContainer queue=root usedCapacity=0.6875 absoluteUsedCapacity=0.6875 used=<memory:11264, vCores:10> cluster=<memory:16384, vCores:16>
2017-01-03 11:40:01,811 INFO org.apache.hadoop.yarn.server.resourcemanager.rmcontainer.RMContainerImpl: container_1483412440498_0003_01_000011 Container Transitioned from ACQUIRED to RUNNING
2017-01-03 11:40:01,811 INFO org.apache.hadoop.yarn.server.resourcemanager.rmcontainer.RMContainerImpl: container_1483412440498_0003_01_000004 Container Transitioned from RUNNING to COMPLETED
2017-01-03 11:40:01,811 INFO org.apache.hadoop.yarn.server.resourcemanager.scheduler.common.fica.FiCaSchedulerApp: Completed container: container_1483412440498_0003_01_000004 in state: COMPLETED event:FINISHED
2017-01-03 11:40:01,812 INFO org.apache.hadoop.yarn.server.resourcemanager.RMAuditLogger: USER=root	OPERATION=AM Released Container	TARGET=SchedulerApp	RESULT=SUCCESS	APPID=application_1483412440498_0003	CONTAINERID=container_1483412440498_0003_01_000004
2017-01-03 11:40:01,812 INFO org.apache.hadoop.yarn.server.resourcemanager.scheduler.SchedulerNode: Released container container_1483412440498_0003_01_000004 of capacity <memory:1024, vCores:1> on host tfs03:45427, which currently has 5 containers, <memory:6144, vCores:5> used and <memory:2048, vCores:3> available, release resources=true
2017-01-03 11:40:01,812 INFO org.apache.hadoop.yarn.server.resourcemanager.scheduler.capacity.LeafQueue: default used=<memory:10240, vCores:9> numContainers=9 user=root user-resources=<memory:10240, vCores:9>
2017-01-03 11:40:01,812 INFO org.apache.hadoop.yarn.server.resourcemanager.scheduler.capacity.LeafQueue: completedContainer container=Container: [ContainerId: container_1483412440498_0003_01_000004, NodeId: tfs03:45427, NodeHttpAddress: tfs03:8042, Resource: <memory:1024, vCores:1>, Priority: 20, Token: Token { kind: ContainerToken, service: 192.168.50.13:45427 }, ] queue=default: capacity=1.0, absoluteCapacity=1.0, usedResources=<memory:10240, vCores:9>, usedCapacity=0.625, absoluteUsedCapacity=0.625, numApps=1, numContainers=9 cluster=<memory:16384, vCores:16>
2017-01-03 11:40:01,813 INFO org.apache.hadoop.yarn.server.resourcemanager.scheduler.capacity.ParentQueue: completedContainer queue=root usedCapacity=0.625 absoluteUsedCapacity=0.625 used=<memory:10240, vCores:9> cluster=<memory:16384, vCores:16>
2017-01-03 11:40:01,813 INFO org.apache.hadoop.yarn.server.resourcemanager.scheduler.capacity.ParentQueue: Re-sorting completed queue: root.default stats: default: capacity=1.0, absoluteCapacity=1.0, usedResources=<memory:10240, vCores:9>, usedCapacity=0.625, absoluteUsedCapacity=0.625, numApps=1, numContainers=9
2017-01-03 11:40:01,813 INFO org.apache.hadoop.yarn.server.resourcemanager.scheduler.capacity.CapacityScheduler: Application attempt appattempt_1483412440498_0003_000001 released container container_1483412440498_0003_01_000004 on node: host: tfs03:45427 #containers=5 available=<memory:2048, vCores:3> used=<memory:6144, vCores:5> with event: FINISHED
2017-01-03 11:40:01,813 INFO org.apache.hadoop.yarn.server.resourcemanager.rmcontainer.RMContainerImpl: container_1483412440498_0003_01_000013 Container Transitioned from NEW to ALLOCATED
2017-01-03 11:40:01,813 INFO org.apache.hadoop.yarn.server.resourcemanager.RMAuditLogger: USER=root	OPERATION=AM Allocated Container	TARGET=SchedulerApp	RESULT=SUCCESS	APPID=application_1483412440498_0003	CONTAINERID=container_1483412440498_0003_01_000013
2017-01-03 11:40:01,813 INFO org.apache.hadoop.yarn.server.resourcemanager.scheduler.SchedulerNode: Assigned container container_1483412440498_0003_01_000013 of capacity <memory:1024, vCores:1> on host tfs03:45427, which has 6 containers, <memory:7168, vCores:6> used and <memory:1024, vCores:2> available after allocation
2017-01-03 11:40:01,813 INFO org.apache.hadoop.yarn.server.resourcemanager.scheduler.capacity.LeafQueue: assignedContainer application attempt=appattempt_1483412440498_0003_000001 container=Container: [ContainerId: container_1483412440498_0003_01_000013, NodeId: tfs03:45427, NodeHttpAddress: tfs03:8042, Resource: <memory:1024, vCores:1>, Priority: 10, Token: null, ] queue=default: capacity=1.0, absoluteCapacity=1.0, usedResources=<memory:10240, vCores:9>, usedCapacity=0.625, absoluteUsedCapacity=0.625, numApps=1, numContainers=9 clusterResource=<memory:16384, vCores:16> type=OFF_SWITCH
2017-01-03 11:40:01,814 INFO org.apache.hadoop.yarn.server.resourcemanager.scheduler.capacity.ParentQueue: Re-sorting assigned queue: root.default stats: default: capacity=1.0, absoluteCapacity=1.0, usedResources=<memory:11264, vCores:10>, usedCapacity=0.6875, absoluteUsedCapacity=0.6875, numApps=1, numContainers=10
2017-01-03 11:40:01,814 INFO org.apache.hadoop.yarn.server.resourcemanager.scheduler.capacity.ParentQueue: assignedContainer queue=root usedCapacity=0.6875 absoluteUsedCapacity=0.6875 used=<memory:11264, vCores:10> cluster=<memory:16384, vCores:16>
2017-01-03 11:40:02,566 INFO org.apache.hadoop.yarn.server.resourcemanager.scheduler.AppSchedulingInfo: checking for deactivate of application :application_1483412440498_0003
2017-01-03 11:40:02,569 INFO org.apache.hadoop.yarn.server.resourcemanager.rmcontainer.RMContainerImpl: container_1483412440498_0003_01_000012 Container Transitioned from ALLOCATED to ACQUIRED
2017-01-03 11:40:02,570 INFO org.apache.hadoop.yarn.server.resourcemanager.rmcontainer.RMContainerImpl: container_1483412440498_0003_01_000013 Container Transitioned from ALLOCATED to ACQUIRED
2017-01-03 11:40:03,575 INFO org.apache.hadoop.yarn.server.resourcemanager.rmcontainer.RMContainerImpl: container_1483412440498_0003_01_000012 Container Transitioned from ACQUIRED to RELEASED
2017-01-03 11:40:03,575 INFO org.apache.hadoop.yarn.server.resourcemanager.scheduler.common.fica.FiCaSchedulerApp: Completed container: container_1483412440498_0003_01_000012 in state: RELEASED event:RELEASED
2017-01-03 11:40:03,575 INFO org.apache.hadoop.yarn.server.resourcemanager.RMAuditLogger: USER=root	IP=192.168.50.13	OPERATION=AM Released Container	TARGET=SchedulerApp	RESULT=SUCCESS	APPID=application_1483412440498_0003	CONTAINERID=container_1483412440498_0003_01_000012
2017-01-03 11:40:03,575 INFO org.apache.hadoop.yarn.server.resourcemanager.scheduler.SchedulerNode: Released container container_1483412440498_0003_01_000012 of capacity <memory:1024, vCores:1> on host tfs04:38559, which currently has 3 containers, <memory:3072, vCores:3> used and <memory:5120, vCores:5> available, release resources=true
2017-01-03 11:40:03,576 INFO org.apache.hadoop.yarn.server.resourcemanager.scheduler.capacity.LeafQueue: default used=<memory:10240, vCores:9> numContainers=9 user=root user-resources=<memory:10240, vCores:9>
2017-01-03 11:40:03,576 INFO org.apache.hadoop.yarn.server.resourcemanager.scheduler.capacity.LeafQueue: completedContainer container=Container: [ContainerId: container_1483412440498_0003_01_000012, NodeId: tfs04:38559, NodeHttpAddress: tfs04:8042, Resource: <memory:1024, vCores:1>, Priority: 10, Token: Token { kind: ContainerToken, service: 192.168.50.14:38559 }, ] queue=default: capacity=1.0, absoluteCapacity=1.0, usedResources=<memory:10240, vCores:9>, usedCapacity=0.625, absoluteUsedCapacity=0.625, numApps=1, numContainers=9 cluster=<memory:16384, vCores:16>
2017-01-03 11:40:03,576 INFO org.apache.hadoop.yarn.server.resourcemanager.scheduler.capacity.ParentQueue: completedContainer queue=root usedCapacity=0.625 absoluteUsedCapacity=0.625 used=<memory:10240, vCores:9> cluster=<memory:16384, vCores:16>
2017-01-03 11:40:03,576 INFO org.apache.hadoop.yarn.server.resourcemanager.scheduler.capacity.ParentQueue: Re-sorting completed queue: root.default stats: default: capacity=1.0, absoluteCapacity=1.0, usedResources=<memory:10240, vCores:9>, usedCapacity=0.625, absoluteUsedCapacity=0.625, numApps=1, numContainers=9
2017-01-03 11:40:03,577 INFO org.apache.hadoop.yarn.server.resourcemanager.scheduler.capacity.CapacityScheduler: Application attempt appattempt_1483412440498_0003_000001 released container container_1483412440498_0003_01_000012 on node: host: tfs04:38559 #containers=3 available=<memory:5120, vCores:5> used=<memory:3072, vCores:3> with event: RELEASED
2017-01-03 11:40:03,577 INFO org.apache.hadoop.yarn.server.resourcemanager.rmcontainer.RMContainerImpl: container_1483412440498_0003_01_000013 Container Transitioned from ACQUIRED to RELEASED
2017-01-03 11:40:03,577 INFO org.apache.hadoop.yarn.server.resourcemanager.scheduler.common.fica.FiCaSchedulerApp: Completed container: container_1483412440498_0003_01_000013 in state: RELEASED event:RELEASED
2017-01-03 11:40:03,577 INFO org.apache.hadoop.yarn.server.resourcemanager.RMAuditLogger: USER=root	IP=192.168.50.13	OPERATION=AM Released Container	TARGET=SchedulerApp	RESULT=SUCCESS	APPID=application_1483412440498_0003	CONTAINERID=container_1483412440498_0003_01_000013
2017-01-03 11:40:03,578 INFO org.apache.hadoop.yarn.server.resourcemanager.scheduler.SchedulerNode: Released container container_1483412440498_0003_01_000013 of capacity <memory:1024, vCores:1> on host tfs03:45427, which currently has 5 containers, <memory:6144, vCores:5> used and <memory:2048, vCores:3> available, release resources=true
2017-01-03 11:40:03,578 INFO org.apache.hadoop.yarn.server.resourcemanager.scheduler.capacity.LeafQueue: default used=<memory:9216, vCores:8> numContainers=8 user=root user-resources=<memory:9216, vCores:8>
2017-01-03 11:40:03,579 INFO org.apache.hadoop.yarn.server.resourcemanager.scheduler.capacity.LeafQueue: completedContainer container=Container: [ContainerId: container_1483412440498_0003_01_000013, NodeId: tfs03:45427, NodeHttpAddress: tfs03:8042, Resource: <memory:1024, vCores:1>, Priority: 10, Token: Token { kind: ContainerToken, service: 192.168.50.13:45427 }, ] queue=default: capacity=1.0, absoluteCapacity=1.0, usedResources=<memory:9216, vCores:8>, usedCapacity=0.5625, absoluteUsedCapacity=0.5625, numApps=1, numContainers=8 cluster=<memory:16384, vCores:16>
2017-01-03 11:40:03,579 INFO org.apache.hadoop.yarn.server.resourcemanager.scheduler.capacity.ParentQueue: completedContainer queue=root usedCapacity=0.5625 absoluteUsedCapacity=0.5625 used=<memory:9216, vCores:8> cluster=<memory:16384, vCores:16>
2017-01-03 11:40:03,579 INFO org.apache.hadoop.yarn.server.resourcemanager.scheduler.capacity.ParentQueue: Re-sorting completed queue: root.default stats: default: capacity=1.0, absoluteCapacity=1.0, usedResources=<memory:9216, vCores:8>, usedCapacity=0.5625, absoluteUsedCapacity=0.5625, numApps=1, numContainers=8
2017-01-03 11:40:03,579 INFO org.apache.hadoop.yarn.server.resourcemanager.scheduler.capacity.CapacityScheduler: Application attempt appattempt_1483412440498_0003_000001 released container container_1483412440498_0003_01_000013 on node: host: tfs03:45427 #containers=5 available=<memory:2048, vCores:3> used=<memory:6144, vCores:5> with event: RELEASED
2017-01-03 11:40:13,830 INFO org.apache.hadoop.yarn.server.resourcemanager.rmcontainer.RMContainerImpl: container_1483412440498_0003_01_000014 Container Transitioned from NEW to ALLOCATED
2017-01-03 11:40:13,830 INFO org.apache.hadoop.yarn.server.resourcemanager.RMAuditLogger: USER=root	OPERATION=AM Allocated Container	TARGET=SchedulerApp	RESULT=SUCCESS	APPID=application_1483412440498_0003	CONTAINERID=container_1483412440498_0003_01_000014
2017-01-03 11:40:13,831 INFO org.apache.hadoop.yarn.server.resourcemanager.scheduler.SchedulerNode: Assigned container container_1483412440498_0003_01_000014 of capacity <memory:1024, vCores:1> on host tfs03:45427, which has 6 containers, <memory:7168, vCores:6> used and <memory:1024, vCores:2> available after allocation
2017-01-03 11:40:13,831 INFO org.apache.hadoop.yarn.server.resourcemanager.scheduler.capacity.LeafQueue: assignedContainer application attempt=appattempt_1483412440498_0003_000001 container=Container: [ContainerId: container_1483412440498_0003_01_000014, NodeId: tfs03:45427, NodeHttpAddress: tfs03:8042, Resource: <memory:1024, vCores:1>, Priority: 20, Token: null, ] queue=default: capacity=1.0, absoluteCapacity=1.0, usedResources=<memory:9216, vCores:8>, usedCapacity=0.5625, absoluteUsedCapacity=0.5625, numApps=1, numContainers=8 clusterResource=<memory:16384, vCores:16> type=NODE_LOCAL
2017-01-03 11:40:13,831 INFO org.apache.hadoop.yarn.server.resourcemanager.scheduler.capacity.ParentQueue: Re-sorting assigned queue: root.default stats: default: capacity=1.0, absoluteCapacity=1.0, usedResources=<memory:10240, vCores:9>, usedCapacity=0.625, absoluteUsedCapacity=0.625, numApps=1, numContainers=9
2017-01-03 11:40:13,831 INFO org.apache.hadoop.yarn.server.resourcemanager.scheduler.capacity.ParentQueue: assignedContainer queue=root usedCapacity=0.625 absoluteUsedCapacity=0.625 used=<memory:10240, vCores:9> cluster=<memory:16384, vCores:16>
2017-01-03 11:40:14,607 INFO org.apache.hadoop.yarn.server.resourcemanager.rmcontainer.RMContainerImpl: container_1483412440498_0003_01_000014 Container Transitioned from ALLOCATED to ACQUIRED
2017-01-03 11:40:14,830 INFO org.apache.hadoop.yarn.server.resourcemanager.rmcontainer.RMContainerImpl: container_1483412440498_0003_01_000014 Container Transitioned from ACQUIRED to RUNNING
2017-01-03 11:40:15,612 INFO org.apache.hadoop.yarn.server.resourcemanager.scheduler.AppSchedulingInfo: checking for deactivate of application :application_1483412440498_0003
2017-01-03 11:40:29,063 INFO org.apache.hadoop.yarn.server.resourcemanager.rmcontainer.RMContainerImpl: container_1483412440498_0003_01_000002 Container Transitioned from RUNNING to COMPLETED
2017-01-03 11:40:29,063 INFO org.apache.hadoop.yarn.server.resourcemanager.scheduler.common.fica.FiCaSchedulerApp: Completed container: container_1483412440498_0003_01_000002 in state: COMPLETED event:FINISHED
2017-01-03 11:40:29,063 INFO org.apache.hadoop.yarn.server.resourcemanager.RMAuditLogger: USER=root	OPERATION=AM Released Container	TARGET=SchedulerApp	RESULT=SUCCESS	APPID=application_1483412440498_0003	CONTAINERID=container_1483412440498_0003_01_000002
2017-01-03 11:40:29,063 INFO org.apache.hadoop.yarn.server.resourcemanager.scheduler.SchedulerNode: Released container container_1483412440498_0003_01_000002 of capacity <memory:1024, vCores:1> on host tfs03:45427, which currently has 5 containers, <memory:6144, vCores:5> used and <memory:2048, vCores:3> available, release resources=true
2017-01-03 11:40:29,063 INFO org.apache.hadoop.yarn.server.resourcemanager.scheduler.capacity.LeafQueue: default used=<memory:9216, vCores:8> numContainers=8 user=root user-resources=<memory:9216, vCores:8>
2017-01-03 11:40:29,064 INFO org.apache.hadoop.yarn.server.resourcemanager.scheduler.capacity.LeafQueue: completedContainer container=Container: [ContainerId: container_1483412440498_0003_01_000002, NodeId: tfs03:45427, NodeHttpAddress: tfs03:8042, Resource: <memory:1024, vCores:1>, Priority: 20, Token: Token { kind: ContainerToken, service: 192.168.50.13:45427 }, ] queue=default: capacity=1.0, absoluteCapacity=1.0, usedResources=<memory:9216, vCores:8>, usedCapacity=0.5625, absoluteUsedCapacity=0.5625, numApps=1, numContainers=8 cluster=<memory:16384, vCores:16>
2017-01-03 11:40:29,064 INFO org.apache.hadoop.yarn.server.resourcemanager.scheduler.capacity.ParentQueue: completedContainer queue=root usedCapacity=0.5625 absoluteUsedCapacity=0.5625 used=<memory:9216, vCores:8> cluster=<memory:16384, vCores:16>
2017-01-03 11:40:29,064 INFO org.apache.hadoop.yarn.server.resourcemanager.scheduler.capacity.ParentQueue: Re-sorting completed queue: root.default stats: default: capacity=1.0, absoluteCapacity=1.0, usedResources=<memory:9216, vCores:8>, usedCapacity=0.5625, absoluteUsedCapacity=0.5625, numApps=1, numContainers=8
2017-01-03 11:40:29,064 INFO org.apache.hadoop.yarn.server.resourcemanager.scheduler.capacity.CapacityScheduler: Application attempt appattempt_1483412440498_0003_000001 released container container_1483412440498_0003_01_000002 on node: host: tfs03:45427 #containers=5 available=<memory:2048, vCores:3> used=<memory:6144, vCores:5> with event: FINISHED
2017-01-03 11:40:30,064 INFO org.apache.hadoop.yarn.server.resourcemanager.rmcontainer.RMContainerImpl: container_1483412440498_0003_01_000014 Container Transitioned from RUNNING to COMPLETED
2017-01-03 11:40:30,064 INFO org.apache.hadoop.yarn.server.resourcemanager.scheduler.common.fica.FiCaSchedulerApp: Completed container: container_1483412440498_0003_01_000014 in state: COMPLETED event:FINISHED
2017-01-03 11:40:30,064 INFO org.apache.hadoop.yarn.server.resourcemanager.RMAuditLogger: USER=root	OPERATION=AM Released Container	TARGET=SchedulerApp	RESULT=SUCCESS	APPID=application_1483412440498_0003	CONTAINERID=container_1483412440498_0003_01_000014
2017-01-03 11:40:30,064 INFO org.apache.hadoop.yarn.server.resourcemanager.scheduler.SchedulerNode: Released container container_1483412440498_0003_01_000014 of capacity <memory:1024, vCores:1> on host tfs03:45427, which currently has 4 containers, <memory:5120, vCores:4> used and <memory:3072, vCores:4> available, release resources=true
2017-01-03 11:40:30,064 INFO org.apache.hadoop.yarn.server.resourcemanager.scheduler.capacity.LeafQueue: default used=<memory:8192, vCores:7> numContainers=7 user=root user-resources=<memory:8192, vCores:7>
2017-01-03 11:40:30,065 INFO org.apache.hadoop.yarn.server.resourcemanager.scheduler.capacity.LeafQueue: completedContainer container=Container: [ContainerId: container_1483412440498_0003_01_000014, NodeId: tfs03:45427, NodeHttpAddress: tfs03:8042, Resource: <memory:1024, vCores:1>, Priority: 20, Token: Token { kind: ContainerToken, service: 192.168.50.13:45427 }, ] queue=default: capacity=1.0, absoluteCapacity=1.0, usedResources=<memory:8192, vCores:7>, usedCapacity=0.5, absoluteUsedCapacity=0.5, numApps=1, numContainers=7 cluster=<memory:16384, vCores:16>
2017-01-03 11:40:30,065 INFO org.apache.hadoop.yarn.server.resourcemanager.scheduler.capacity.ParentQueue: completedContainer queue=root usedCapacity=0.5 absoluteUsedCapacity=0.5 used=<memory:8192, vCores:7> cluster=<memory:16384, vCores:16>
2017-01-03 11:40:30,065 INFO org.apache.hadoop.yarn.server.resourcemanager.scheduler.capacity.ParentQueue: Re-sorting completed queue: root.default stats: default: capacity=1.0, absoluteCapacity=1.0, usedResources=<memory:8192, vCores:7>, usedCapacity=0.5, absoluteUsedCapacity=0.5, numApps=1, numContainers=7
2017-01-03 11:40:30,065 INFO org.apache.hadoop.yarn.server.resourcemanager.scheduler.capacity.CapacityScheduler: Application attempt appattempt_1483412440498_0003_000001 released container container_1483412440498_0003_01_000014 on node: host: tfs03:45427 #containers=4 available=<memory:3072, vCores:4> used=<memory:5120, vCores:4> with event: FINISHED
2017-01-03 11:40:41,612 INFO org.apache.hadoop.yarn.server.resourcemanager.rmcontainer.RMContainerImpl: container_1483412440498_0003_01_000005 Container Transitioned from RUNNING to COMPLETED
2017-01-03 11:40:41,612 INFO org.apache.hadoop.yarn.server.resourcemanager.scheduler.common.fica.FiCaSchedulerApp: Completed container: container_1483412440498_0003_01_000005 in state: COMPLETED event:FINISHED
2017-01-03 11:40:41,612 INFO org.apache.hadoop.yarn.server.resourcemanager.RMAuditLogger: USER=root	OPERATION=AM Released Container	TARGET=SchedulerApp	RESULT=SUCCESS	APPID=application_1483412440498_0003	CONTAINERID=container_1483412440498_0003_01_000005
2017-01-03 11:40:41,612 INFO org.apache.hadoop.yarn.server.resourcemanager.scheduler.SchedulerNode: Released container container_1483412440498_0003_01_000005 of capacity <memory:1024, vCores:1> on host tfs03:45427, which currently has 3 containers, <memory:4096, vCores:3> used and <memory:4096, vCores:5> available, release resources=true
2017-01-03 11:40:41,612 INFO org.apache.hadoop.yarn.server.resourcemanager.scheduler.capacity.LeafQueue: default used=<memory:7168, vCores:6> numContainers=6 user=root user-resources=<memory:7168, vCores:6>
2017-01-03 11:40:41,613 INFO org.apache.hadoop.yarn.server.resourcemanager.scheduler.capacity.LeafQueue: completedContainer container=Container: [ContainerId: container_1483412440498_0003_01_000005, NodeId: tfs03:45427, NodeHttpAddress: tfs03:8042, Resource: <memory:1024, vCores:1>, Priority: 20, Token: Token { kind: ContainerToken, service: 192.168.50.13:45427 }, ] queue=default: capacity=1.0, absoluteCapacity=1.0, usedResources=<memory:7168, vCores:6>, usedCapacity=0.4375, absoluteUsedCapacity=0.4375, numApps=1, numContainers=6 cluster=<memory:16384, vCores:16>
2017-01-03 11:40:41,613 INFO org.apache.hadoop.yarn.server.resourcemanager.scheduler.capacity.ParentQueue: completedContainer queue=root usedCapacity=0.4375 absoluteUsedCapacity=0.4375 used=<memory:7168, vCores:6> cluster=<memory:16384, vCores:16>
2017-01-03 11:40:41,613 INFO org.apache.hadoop.yarn.server.resourcemanager.scheduler.capacity.ParentQueue: Re-sorting completed queue: root.default stats: default: capacity=1.0, absoluteCapacity=1.0, usedResources=<memory:7168, vCores:6>, usedCapacity=0.4375, absoluteUsedCapacity=0.4375, numApps=1, numContainers=6
2017-01-03 11:40:41,613 INFO org.apache.hadoop.yarn.server.resourcemanager.scheduler.capacity.CapacityScheduler: Application attempt appattempt_1483412440498_0003_000001 released container container_1483412440498_0003_01_000005 on node: host: tfs03:45427 #containers=3 available=<memory:4096, vCores:5> used=<memory:4096, vCores:3> with event: FINISHED
2017-01-03 11:40:41,627 INFO org.apache.hadoop.yarn.server.resourcemanager.rmcontainer.RMContainerImpl: container_1483412440498_0003_01_000007 Container Transitioned from RUNNING to COMPLETED
2017-01-03 11:40:41,627 INFO org.apache.hadoop.yarn.server.resourcemanager.scheduler.common.fica.FiCaSchedulerApp: Completed container: container_1483412440498_0003_01_000007 in state: COMPLETED event:FINISHED
2017-01-03 11:40:41,627 INFO org.apache.hadoop.yarn.server.resourcemanager.RMAuditLogger: USER=root	OPERATION=AM Released Container	TARGET=SchedulerApp	RESULT=SUCCESS	APPID=application_1483412440498_0003	CONTAINERID=container_1483412440498_0003_01_000007
2017-01-03 11:40:41,627 INFO org.apache.hadoop.yarn.server.resourcemanager.scheduler.SchedulerNode: Released container container_1483412440498_0003_01_000007 of capacity <memory:1024, vCores:1> on host tfs04:38559, which currently has 2 containers, <memory:2048, vCores:2> used and <memory:6144, vCores:6> available, release resources=true
2017-01-03 11:40:41,627 INFO org.apache.hadoop.yarn.server.resourcemanager.scheduler.capacity.LeafQueue: default used=<memory:6144, vCores:5> numContainers=5 user=root user-resources=<memory:6144, vCores:5>
2017-01-03 11:40:41,628 INFO org.apache.hadoop.yarn.server.resourcemanager.scheduler.capacity.LeafQueue: completedContainer container=Container: [ContainerId: container_1483412440498_0003_01_000007, NodeId: tfs04:38559, NodeHttpAddress: tfs04:8042, Resource: <memory:1024, vCores:1>, Priority: 20, Token: Token { kind: ContainerToken, service: 192.168.50.14:38559 }, ] queue=default: capacity=1.0, absoluteCapacity=1.0, usedResources=<memory:6144, vCores:5>, usedCapacity=0.375, absoluteUsedCapacity=0.375, numApps=1, numContainers=5 cluster=<memory:16384, vCores:16>
2017-01-03 11:40:41,628 INFO org.apache.hadoop.yarn.server.resourcemanager.scheduler.capacity.ParentQueue: completedContainer queue=root usedCapacity=0.375 absoluteUsedCapacity=0.375 used=<memory:6144, vCores:5> cluster=<memory:16384, vCores:16>
2017-01-03 11:40:41,628 INFO org.apache.hadoop.yarn.server.resourcemanager.scheduler.capacity.ParentQueue: Re-sorting completed queue: root.default stats: default: capacity=1.0, absoluteCapacity=1.0, usedResources=<memory:6144, vCores:5>, usedCapacity=0.375, absoluteUsedCapacity=0.375, numApps=1, numContainers=5
2017-01-03 11:40:41,628 INFO org.apache.hadoop.yarn.server.resourcemanager.scheduler.capacity.CapacityScheduler: Application attempt appattempt_1483412440498_0003_000001 released container container_1483412440498_0003_01_000007 on node: host: tfs04:38559 #containers=2 available=<memory:6144, vCores:6> used=<memory:2048, vCores:2> with event: FINISHED
2017-01-03 11:40:49,104 INFO org.apache.hadoop.yarn.server.resourcemanager.rmcontainer.RMContainerImpl: container_1483412440498_0003_01_000010 Container Transitioned from RUNNING to COMPLETED
2017-01-03 11:40:49,104 INFO org.apache.hadoop.yarn.server.resourcemanager.scheduler.common.fica.FiCaSchedulerApp: Completed container: container_1483412440498_0003_01_000010 in state: COMPLETED event:FINISHED
2017-01-03 11:40:49,104 INFO org.apache.hadoop.yarn.server.resourcemanager.RMAuditLogger: USER=root	OPERATION=AM Released Container	TARGET=SchedulerApp	RESULT=SUCCESS	APPID=application_1483412440498_0003	CONTAINERID=container_1483412440498_0003_01_000010
2017-01-03 11:40:49,104 INFO org.apache.hadoop.yarn.server.resourcemanager.scheduler.SchedulerNode: Released container container_1483412440498_0003_01_000010 of capacity <memory:1024, vCores:1> on host tfs04:38559, which currently has 1 containers, <memory:1024, vCores:1> used and <memory:7168, vCores:7> available, release resources=true
2017-01-03 11:40:49,104 INFO org.apache.hadoop.yarn.server.resourcemanager.scheduler.capacity.LeafQueue: default used=<memory:5120, vCores:4> numContainers=4 user=root user-resources=<memory:5120, vCores:4>
2017-01-03 11:40:49,106 INFO org.apache.hadoop.yarn.server.resourcemanager.scheduler.capacity.LeafQueue: completedContainer container=Container: [ContainerId: container_1483412440498_0003_01_000010, NodeId: tfs04:38559, NodeHttpAddress: tfs04:8042, Resource: <memory:1024, vCores:1>, Priority: 10, Token: Token { kind: ContainerToken, service: 192.168.50.14:38559 }, ] queue=default: capacity=1.0, absoluteCapacity=1.0, usedResources=<memory:5120, vCores:4>, usedCapacity=0.3125, absoluteUsedCapacity=0.3125, numApps=1, numContainers=4 cluster=<memory:16384, vCores:16>
2017-01-03 11:40:49,106 INFO org.apache.hadoop.yarn.server.resourcemanager.scheduler.capacity.ParentQueue: completedContainer queue=root usedCapacity=0.3125 absoluteUsedCapacity=0.3125 used=<memory:5120, vCores:4> cluster=<memory:16384, vCores:16>
2017-01-03 11:40:49,106 INFO org.apache.hadoop.yarn.server.resourcemanager.scheduler.capacity.ParentQueue: Re-sorting completed queue: root.default stats: default: capacity=1.0, absoluteCapacity=1.0, usedResources=<memory:5120, vCores:4>, usedCapacity=0.3125, absoluteUsedCapacity=0.3125, numApps=1, numContainers=4
2017-01-03 11:40:49,106 INFO org.apache.hadoop.yarn.server.resourcemanager.scheduler.capacity.CapacityScheduler: Application attempt appattempt_1483412440498_0003_000001 released container container_1483412440498_0003_01_000010 on node: host: tfs04:38559 #containers=1 available=<memory:7168, vCores:7> used=<memory:1024, vCores:1> with event: FINISHED
2017-01-03 11:40:49,325 INFO org.apache.hadoop.yarn.server.resourcemanager.rmcontainer.RMContainerImpl: container_1483412440498_0003_01_000011 Container Transitioned from RUNNING to COMPLETED
2017-01-03 11:40:49,325 INFO org.apache.hadoop.yarn.server.resourcemanager.scheduler.common.fica.FiCaSchedulerApp: Completed container: container_1483412440498_0003_01_000011 in state: COMPLETED event:FINISHED
2017-01-03 11:40:49,325 INFO org.apache.hadoop.yarn.server.resourcemanager.RMAuditLogger: USER=root	OPERATION=AM Released Container	TARGET=SchedulerApp	RESULT=SUCCESS	APPID=application_1483412440498_0003	CONTAINERID=container_1483412440498_0003_01_000011
2017-01-03 11:40:49,325 INFO org.apache.hadoop.yarn.server.resourcemanager.scheduler.SchedulerNode: Released container container_1483412440498_0003_01_000011 of capacity <memory:1024, vCores:1> on host tfs03:45427, which currently has 2 containers, <memory:3072, vCores:2> used and <memory:5120, vCores:6> available, release resources=true
2017-01-03 11:40:49,326 INFO org.apache.hadoop.yarn.server.resourcemanager.scheduler.capacity.LeafQueue: default used=<memory:4096, vCores:3> numContainers=3 user=root user-resources=<memory:4096, vCores:3>
2017-01-03 11:40:49,326 INFO org.apache.hadoop.yarn.server.resourcemanager.scheduler.capacity.LeafQueue: completedContainer container=Container: [ContainerId: container_1483412440498_0003_01_000011, NodeId: tfs03:45427, NodeHttpAddress: tfs03:8042, Resource: <memory:1024, vCores:1>, Priority: 10, Token: Token { kind: ContainerToken, service: 192.168.50.13:45427 }, ] queue=default: capacity=1.0, absoluteCapacity=1.0, usedResources=<memory:4096, vCores:3>, usedCapacity=0.25, absoluteUsedCapacity=0.25, numApps=1, numContainers=3 cluster=<memory:16384, vCores:16>
2017-01-03 11:40:49,326 INFO org.apache.hadoop.yarn.server.resourcemanager.scheduler.capacity.ParentQueue: completedContainer queue=root usedCapacity=0.25 absoluteUsedCapacity=0.25 used=<memory:4096, vCores:3> cluster=<memory:16384, vCores:16>
2017-01-03 11:40:49,326 INFO org.apache.hadoop.yarn.server.resourcemanager.scheduler.capacity.ParentQueue: Re-sorting completed queue: root.default stats: default: capacity=1.0, absoluteCapacity=1.0, usedResources=<memory:4096, vCores:3>, usedCapacity=0.25, absoluteUsedCapacity=0.25, numApps=1, numContainers=3
2017-01-03 11:40:49,326 INFO org.apache.hadoop.yarn.server.resourcemanager.scheduler.capacity.CapacityScheduler: Application attempt appattempt_1483412440498_0003_000001 released container container_1483412440498_0003_01_000011 on node: host: tfs03:45427 #containers=2 available=<memory:5120, vCores:6> used=<memory:3072, vCores:2> with event: FINISHED
2017-01-03 11:40:49,498 INFO org.apache.hadoop.yarn.server.resourcemanager.rmcontainer.RMContainerImpl: container_1483412440498_0003_01_000008 Container Transitioned from RUNNING to COMPLETED
2017-01-03 11:40:49,498 INFO org.apache.hadoop.yarn.server.resourcemanager.scheduler.common.fica.FiCaSchedulerApp: Completed container: container_1483412440498_0003_01_000008 in state: COMPLETED event:FINISHED
2017-01-03 11:40:49,498 INFO org.apache.hadoop.yarn.server.resourcemanager.RMAuditLogger: USER=root	OPERATION=AM Released Container	TARGET=SchedulerApp	RESULT=SUCCESS	APPID=application_1483412440498_0003	CONTAINERID=container_1483412440498_0003_01_000008
2017-01-03 11:40:49,498 INFO org.apache.hadoop.yarn.server.resourcemanager.scheduler.SchedulerNode: Released container container_1483412440498_0003_01_000008 of capacity <memory:1024, vCores:1> on host tfs04:38559, which currently has 0 containers, <memory:0, vCores:0> used and <memory:8192, vCores:8> available, release resources=true
2017-01-03 11:40:49,499 INFO org.apache.hadoop.yarn.server.resourcemanager.scheduler.capacity.LeafQueue: default used=<memory:3072, vCores:2> numContainers=2 user=root user-resources=<memory:3072, vCores:2>
2017-01-03 11:40:49,499 INFO org.apache.hadoop.yarn.server.resourcemanager.scheduler.capacity.LeafQueue: completedContainer container=Container: [ContainerId: container_1483412440498_0003_01_000008, NodeId: tfs04:38559, NodeHttpAddress: tfs04:8042, Resource: <memory:1024, vCores:1>, Priority: 10, Token: Token { kind: ContainerToken, service: 192.168.50.14:38559 }, ] queue=default: capacity=1.0, absoluteCapacity=1.0, usedResources=<memory:3072, vCores:2>, usedCapacity=0.1875, absoluteUsedCapacity=0.1875, numApps=1, numContainers=2 cluster=<memory:16384, vCores:16>
2017-01-03 11:40:49,500 INFO org.apache.hadoop.yarn.server.resourcemanager.scheduler.capacity.ParentQueue: completedContainer queue=root usedCapacity=0.1875 absoluteUsedCapacity=0.1875 used=<memory:3072, vCores:2> cluster=<memory:16384, vCores:16>
2017-01-03 11:40:49,500 INFO org.apache.hadoop.yarn.server.resourcemanager.scheduler.capacity.ParentQueue: Re-sorting completed queue: root.default stats: default: capacity=1.0, absoluteCapacity=1.0, usedResources=<memory:3072, vCores:2>, usedCapacity=0.1875, absoluteUsedCapacity=0.1875, numApps=1, numContainers=2
2017-01-03 11:40:49,500 INFO org.apache.hadoop.yarn.server.resourcemanager.scheduler.capacity.CapacityScheduler: Application attempt appattempt_1483412440498_0003_000001 released container container_1483412440498_0003_01_000008 on node: host: tfs04:38559 #containers=0 available=<memory:8192, vCores:8> used=<memory:0, vCores:0> with event: FINISHED
2017-01-03 11:40:49,521 INFO org.apache.hadoop.yarn.server.resourcemanager.rmcontainer.RMContainerImpl: container_1483412440498_0003_01_000009 Container Transitioned from RUNNING to COMPLETED
2017-01-03 11:40:49,521 INFO org.apache.hadoop.yarn.server.resourcemanager.scheduler.common.fica.FiCaSchedulerApp: Completed container: container_1483412440498_0003_01_000009 in state: COMPLETED event:FINISHED
2017-01-03 11:40:49,522 INFO org.apache.hadoop.yarn.server.resourcemanager.RMAuditLogger: USER=root	OPERATION=AM Released Container	TARGET=SchedulerApp	RESULT=SUCCESS	APPID=application_1483412440498_0003	CONTAINERID=container_1483412440498_0003_01_000009
2017-01-03 11:40:49,522 INFO org.apache.hadoop.yarn.server.resourcemanager.scheduler.SchedulerNode: Released container container_1483412440498_0003_01_000009 of capacity <memory:1024, vCores:1> on host tfs03:45427, which currently has 1 containers, <memory:2048, vCores:1> used and <memory:6144, vCores:7> available, release resources=true
2017-01-03 11:40:49,522 INFO org.apache.hadoop.yarn.server.resourcemanager.scheduler.capacity.LeafQueue: default used=<memory:2048, vCores:1> numContainers=1 user=root user-resources=<memory:2048, vCores:1>
2017-01-03 11:40:49,522 INFO org.apache.hadoop.yarn.server.resourcemanager.scheduler.capacity.LeafQueue: completedContainer container=Container: [ContainerId: container_1483412440498_0003_01_000009, NodeId: tfs03:45427, NodeHttpAddress: tfs03:8042, Resource: <memory:1024, vCores:1>, Priority: 10, Token: Token { kind: ContainerToken, service: 192.168.50.13:45427 }, ] queue=default: capacity=1.0, absoluteCapacity=1.0, usedResources=<memory:2048, vCores:1>, usedCapacity=0.125, absoluteUsedCapacity=0.125, numApps=1, numContainers=1 cluster=<memory:16384, vCores:16>
2017-01-03 11:40:49,522 INFO org.apache.hadoop.yarn.server.resourcemanager.scheduler.capacity.ParentQueue: completedContainer queue=root usedCapacity=0.125 absoluteUsedCapacity=0.125 used=<memory:2048, vCores:1> cluster=<memory:16384, vCores:16>
2017-01-03 11:40:49,522 INFO org.apache.hadoop.yarn.server.resourcemanager.scheduler.capacity.ParentQueue: Re-sorting completed queue: root.default stats: default: capacity=1.0, absoluteCapacity=1.0, usedResources=<memory:2048, vCores:1>, usedCapacity=0.125, absoluteUsedCapacity=0.125, numApps=1, numContainers=1
2017-01-03 11:40:49,522 INFO org.apache.hadoop.yarn.server.resourcemanager.scheduler.capacity.CapacityScheduler: Application attempt appattempt_1483412440498_0003_000001 released container container_1483412440498_0003_01_000009 on node: host: tfs03:45427 #containers=1 available=<memory:6144, vCores:7> used=<memory:2048, vCores:1> with event: FINISHED
2017-01-03 11:40:49,662 INFO org.apache.hadoop.yarn.server.resourcemanager.rmapp.attempt.RMAppAttemptImpl: Updating application attempt appattempt_1483412440498_0003_000001 with final state: FINISHING, and exit status: -1000
2017-01-03 11:40:49,663 INFO org.apache.hadoop.yarn.server.resourcemanager.rmapp.attempt.RMAppAttemptImpl: appattempt_1483412440498_0003_000001 State change from RUNNING to FINAL_SAVING
2017-01-03 11:40:49,663 INFO org.apache.hadoop.yarn.server.resourcemanager.rmapp.RMAppImpl: Updating application application_1483412440498_0003 with final state: FINISHING
2017-01-03 11:40:49,663 INFO org.apache.hadoop.yarn.server.resourcemanager.rmapp.RMAppImpl: application_1483412440498_0003 State change from RUNNING to FINAL_SAVING
2017-01-03 11:40:49,663 INFO org.apache.hadoop.yarn.server.resourcemanager.recovery.RMStateStore: Updating info for app: application_1483412440498_0003
2017-01-03 11:40:49,663 INFO org.apache.hadoop.yarn.server.resourcemanager.rmapp.attempt.RMAppAttemptImpl: appattempt_1483412440498_0003_000001 State change from FINAL_SAVING to FINISHING
2017-01-03 11:40:49,663 INFO org.apache.hadoop.yarn.server.resourcemanager.rmapp.RMAppImpl: application_1483412440498_0003 State change from FINAL_SAVING to FINISHING
2017-01-03 11:40:50,665 INFO org.apache.hadoop.yarn.server.resourcemanager.ApplicationMasterService: application_1483412440498_0003 unregistered successfully. 
2017-01-03 11:40:56,167 INFO org.apache.hadoop.yarn.server.resourcemanager.rmcontainer.RMContainerImpl: container_1483412440498_0003_01_000001 Container Transitioned from RUNNING to COMPLETED
2017-01-03 11:40:56,167 INFO org.apache.hadoop.yarn.server.resourcemanager.ApplicationMasterService: Unregistering app attempt : appattempt_1483412440498_0003_000001
2017-01-03 11:40:56,167 INFO org.apache.hadoop.yarn.server.resourcemanager.scheduler.common.fica.FiCaSchedulerApp: Completed container: container_1483412440498_0003_01_000001 in state: COMPLETED event:FINISHED
2017-01-03 11:40:56,167 INFO org.apache.hadoop.yarn.server.resourcemanager.security.AMRMTokenSecretManager: Application finished, removing password for appattempt_1483412440498_0003_000001
2017-01-03 11:40:56,167 INFO org.apache.hadoop.yarn.server.resourcemanager.RMAuditLogger: USER=root	OPERATION=AM Released Container	TARGET=SchedulerApp	RESULT=SUCCESS	APPID=application_1483412440498_0003	CONTAINERID=container_1483412440498_0003_01_000001
2017-01-03 11:40:56,167 INFO org.apache.hadoop.yarn.server.resourcemanager.scheduler.SchedulerNode: Released container container_1483412440498_0003_01_000001 of capacity <memory:2048, vCores:1> on host tfs03:45427, which currently has 0 containers, <memory:0, vCores:0> used and <memory:8192, vCores:8> available, release resources=true
2017-01-03 11:40:56,167 INFO org.apache.hadoop.yarn.server.resourcemanager.rmapp.attempt.RMAppAttemptImpl: appattempt_1483412440498_0003_000001 State change from FINISHING to FINISHED
2017-01-03 11:40:56,167 INFO org.apache.hadoop.yarn.server.resourcemanager.rmapp.RMAppImpl: application_1483412440498_0003 State change from FINISHING to FINISHED
2017-01-03 11:40:56,167 INFO org.apache.hadoop.yarn.server.resourcemanager.scheduler.capacity.LeafQueue: default used=<memory:0, vCores:0> numContainers=0 user=root user-resources=<memory:0, vCores:0>
2017-01-03 11:40:56,167 INFO org.apache.hadoop.yarn.server.resourcemanager.RMAuditLogger: USER=root	OPERATION=Application Finished - Succeeded	TARGET=RMAppManager	RESULT=SUCCESS	APPID=application_1483412440498_0003
2017-01-03 11:40:56,167 INFO org.apache.hadoop.yarn.server.resourcemanager.scheduler.capacity.LeafQueue: completedContainer container=Container: [ContainerId: container_1483412440498_0003_01_000001, NodeId: tfs03:45427, NodeHttpAddress: tfs03:8042, Resource: <memory:2048, vCores:1>, Priority: 0, Token: Token { kind: ContainerToken, service: 192.168.50.13:45427 }, ] queue=default: capacity=1.0, absoluteCapacity=1.0, usedResources=<memory:0, vCores:0>, usedCapacity=0.0, absoluteUsedCapacity=0.0, numApps=1, numContainers=0 cluster=<memory:16384, vCores:16>
2017-01-03 11:40:56,167 INFO org.apache.hadoop.yarn.server.resourcemanager.scheduler.capacity.ParentQueue: completedContainer queue=root usedCapacity=0.0 absoluteUsedCapacity=0.0 used=<memory:0, vCores:0> cluster=<memory:16384, vCores:16>
2017-01-03 11:40:56,167 INFO org.apache.hadoop.yarn.server.resourcemanager.scheduler.capacity.ParentQueue: Re-sorting completed queue: root.default stats: default: capacity=1.0, absoluteCapacity=1.0, usedResources=<memory:0, vCores:0>, usedCapacity=0.0, absoluteUsedCapacity=0.0, numApps=1, numContainers=0
2017-01-03 11:40:56,167 INFO org.apache.hadoop.yarn.server.resourcemanager.scheduler.capacity.CapacityScheduler: Application attempt appattempt_1483412440498_0003_000001 released container container_1483412440498_0003_01_000001 on node: host: tfs03:45427 #containers=0 available=<memory:8192, vCores:8> used=<memory:0, vCores:0> with event: FINISHED
2017-01-03 11:40:56,167 INFO org.apache.hadoop.yarn.server.resourcemanager.scheduler.capacity.CapacityScheduler: Application Attempt appattempt_1483412440498_0003_000001 is done. finalState=FINISHED
2017-01-03 11:40:56,167 INFO org.apache.hadoop.yarn.server.resourcemanager.scheduler.AppSchedulingInfo: Application application_1483412440498_0003 requests cleared
2017-01-03 11:40:56,167 INFO org.apache.hadoop.yarn.server.resourcemanager.RMAppManager$ApplicationSummary: appId=application_1483412440498_0003,name=select test.* from test join n...test.id\=100(Stage-1),user=root,queue=default,state=FINISHED,trackingUrl=http://Master:8088/proxy/application_1483412440498_0003/,appMasterHost=tfs03,startTime=1483414771826,finishTime=1483414849663,finalStatus=SUCCEEDED,memorySeconds=580513,vcoreSeconds=474,preemptedAMContainers=0,preemptedNonAMContainers=0,preemptedResources=<memory:0\, vCores:0>,applicationType=MAPREDUCE
2017-01-03 11:40:56,168 INFO org.apache.hadoop.yarn.server.resourcemanager.scheduler.capacity.LeafQueue: Application removed - appId: application_1483412440498_0003 user: root queue: default #user-pending-applications: 0 #user-active-applications: 0 #queue-pending-applications: 0 #queue-active-applications: 0
2017-01-03 11:40:56,168 INFO org.apache.hadoop.yarn.server.resourcemanager.amlauncher.AMLauncher: Cleaning master appattempt_1483412440498_0003_000001
2017-01-03 11:40:56,168 INFO org.apache.hadoop.yarn.server.resourcemanager.scheduler.capacity.ParentQueue: Application removed - appId: application_1483412440498_0003 user: root leaf-queue of parent: root #applications: 0
2017-01-03 11:40:57,509 INFO org.apache.hadoop.yarn.server.resourcemanager.scheduler.capacity.CapacityScheduler: Null container completed...
2017-01-03 11:40:57,509 INFO org.apache.hadoop.yarn.server.resourcemanager.scheduler.capacity.CapacityScheduler: Null container completed...
2017-01-03 11:40:58,169 INFO org.apache.hadoop.yarn.server.resourcemanager.scheduler.capacity.CapacityScheduler: Null container completed...
2017-01-03 11:40:58,170 INFO org.apache.hadoop.yarn.server.resourcemanager.scheduler.capacity.CapacityScheduler: Null container completed...
